Workbook
Name SegmentaciónDeDatos_LLAVE_AUTO: #REF!
Name SegmentaciónDeDatos_LLAVE_AUTO: #REF!

Sheet UBER 2025
A1: SEM | B1: CONDUCTOR | C1: AUTO | D1: TAG | E1: SOCIO | F1: PLATAFORMA | G1: APP | H1: GANANCIA | I1: IMPUESTOS | J1: P. AJUSANT | K1: SEGURO | L1: EFECTIVO | M1: PAGO A TERCEROS | N1: TAG | O1: UBER tot | P1: RENTA | Q1: SEM PASADA | R1: FIANZA | S1: MULTA | T1: HOJALATERO | U1: DESCUENTOS | V1: FA | W1: TOTAL | X1: PAGOS | Y1: DEVOLUCIONES | Z1: PAGADO | AA1: ADEUDO | AB1: GANANCIAS TOTALES | AC1: COMENTARIOS
A2: 1 | B2: ADOLFO LOPEZ MARTINEZ | C2: AVEO|2021|OCRE|NEB156A | D2: OHLM023012552 | E2: ASHC | F2: IVETH | G2: UBER | H2: 1943.26 | I2: -16 | J2: 0 | K2: 0 | L2: -758.4 | M2: =-38.8652+32 -> -6.8652 | N2: 0 | O2: =SUM(H2:N2) -> 1161.9948 | P2: -2142.85 | Q2: 0 | R2: 0 | S2: 0 | T2: 0 | U2: 0 | V2: 0 | W2: =+O2+SUM(P2:V2) -> -980.8552 | X2: =IF(W2>=0,W2,0) -> 0 | Y2: =IF(W2<=0,W2,0) -> -980.8552 | Z2: 981 | AA2: =+Y2+Z2 -> 0.1448 | AB2: =+O2-X2+Z2+AA2 -> 2143.1396
A3: 1 | B3: ARACELI CASTILLO GUERRERO | C3: AVEO|2018|GRIS|X59AWG | D3: - | E3: ASHC | F3: ASHC | G3: UBER | H3: 6825.48 | I3: -448 | J3: 0 | K3: 0 | L3: -1537.44 | M3: -136.5096 | N3: 0 | O3: =SUM(H3:N3) -> 4703.5304 | P3: -2142.85 | Q3: 0 | R3: 0 | S3: 0 | T3: 0 | U3: 0 | V3: 0 | W3: =+O3+SUM(P3:V3) -> 2560.6804 | X3: =IF(W3>=0,W3,0) -> 2560.6804 | Y3: =IF(W3<=0,W3,0) -> 0 | Z3: 0 | AA3: =+Y3+Z3 -> 0 | AB3: =+O3-X3+Z3+AA3 -> 2142.85
A4: 1 | B4: CESAR PIÑA BARONA | C4: HYUNDAI|2022|PLATA|D40BKD | D4: OHLM023658024 | E4: ASHC | F4: IVETH | G4: UBER | H4: 0 | I4: 0 | J4: 0 | K4: 0 | L4: 0 | M4: 0 | N4: 0 | O4: =SUM(H4:N4) -> 0 | P4: -2142.85 | Q4: -67 | R4: 0 | S4: 0 | T4: 0 | U4: 0 | V4: 0 | W4: =+O4+SUM(P4:V4) -> -2209.85 | X4: =IF(W4>=0,W4,0) -> 0 | Y4: =IF(W4<=0,W4,0) -> -2209.85 | Z4: 2210 | AA4: =+Y4+Z4 -> 0.15 | AB4: =+O4-X4+Z4+AA4 -> 2210.15
A5: 1 | B5: CLAUDIA LEAÑOS | C5: KIA RIO|2017|ROJO|MYE912A | D5: - | E5: U64 | F5: ASHC | G5: UBER | H5: 3855.54 | I5: -30.4 | J5: 0 | K5: 0 | L5: -2145.89 | M5: -77.1108 | N5: 0 | O5: =SUM(H5:N5) -> 1602.1392 | P5: -2142.85 | Q5: -510.28 | R5: 0 | S5: 0 | T5: 0 | U5: 0 | V5: 0 | W5: =+O5+SUM(P5:V5) -> -1050.9908 | X5: =IF(W5>=0,W5,0) -> 0 | Y5: =IF(W5<=0,W5,0) -> -1050.9908 | Z5: 1051 | AA5: =+Y5+Z5 -> 0.0092 | AB5: =+O5-X5+Z5+AA5 -> 2653.1484
A6: 1 | B6: IVAN MOGUEL PULIDO | C6: VERSA|2023|PLATA|NCT814A | D6: OHLM023012487 | E6: ASHC | F6: ASHC | G6: UBER | H6: 3884.89 | I6: 0 | J6: 0 | K6: 0 | L6: -2355.1 | M6: -90.2478 | N6: -70.97 | O6: =SUM(H6:N6) -> 1368.5722 | P6: -714.28 | Q6: 0 | R6: 0 | S6: 0 | T6: -500 | U6: 0 | V6: 0 | W6: =+O6+SUM(P6:V6) -> 154.2922 | X6: =IF(W6>=0,W6,0) -> 154.2922 | Y6: =IF(W6<=0,W6,0) -> 0 | Z6: 0 | AA6: =+Y6+Z6 -> 0 | AB6: =+O6-X6+Z6+AA6 -> 1214.28
A7: 1 | B7: JESUS AURELIO NUNGARAY CASTILLO | C7: VENTO|2020|GRIS|R66BER | D7: - | E7: ASHC | F7: ASHC | G7: UBER | H7: 4885.68 | I7: 0 | J7: 0 | K7: 0 | L7: -2620.14 | M7: -97.7136 | N7: 0 | O7: =SUM(H7:N7) -> 2167.8264 | P7: -2142.85 | Q7: -683.71 | R7: 0 | S7: 0 | T7: 0 | U7: 0 | V7: 0 | W7: =+O7+SUM(P7:V7) -> -658.7336 | X7: =IF(W7>=0,W7,0) -> 0 | Y7: =IF(W7<=0,W7,0) -> -658.7336 | Z7: 659 | AA7: =+Y7+Z7 -> 0.2664 | AB7: =+O7-X7+Z7+AA7 -> 2827.0928
A8: 1 | B8: JORGE VAZQUEZ HERNANDEZ | C8: AVEO|2018|GRIS|X59AWG | D8: - | E8: ASHC | F8: ASHC | G8: UBER | H8: 9781.33 | I8: 0 | J8: 0 | K8: 0 | L8: -4655.05 | M8: -195.6266 | N8: 0 | O8: =SUM(H8:N8) -> 4930.6534 | P8: -2142.85 | Q8: 0 | R8: 0 | S8: 0 | T8: 0 | U8: 0 | V8: 0 | W8: =+O8+SUM(P8:V8) -> 2787.8034 | X8: =IF(W8>=0,W8,0) -> 2787.8034 | Y8: =IF(W8<=0,W8,0) -> 0 | Z8: 0 | AA8: =+Y8+Z8 -> 0 | AB8: =+O8-X8+Z8+AA8 -> 2142.85
A9: 1 | B9: JOSE GUADALUPE GARCIA MORALES | C9: MARCH|2020|TURQ|N15BKD | D9: OHLM031409071 | E9: ASHC | F9: ASHC | G9: UBER | H9: 5089.85 | I9: -24 | J9: 0 | K9: 0 | L9: -3520.73 | M9: =-101.797+48 -> -53.797 | N9: 0 | O9: =SUM(H9:N9) -> 1491.323 | P9: -2142.85 | Q9: 0 | R9: -500 | S9: 0 | T9: 0 | U9: 0 | V9: 0 | W9: =+O9+SUM(P9:V9) -> -1151.527 | X9: =IF(W9>=0,W9,0) -> 0 | Y9: =IF(W9<=0,W9,0) -> -1151.527 | Z9: 1152 | AA9: =+Y9+Z9 -> 0.473 | AB9: =+O9-X9+Z9+AA9 -> 2643.796
A10: 1 | B10: JOSE JUAN HERNANDEZ MEJIA | C10: VERSA|2017|ACERO|X24APU | D10: OHLM023720345 | E10: ASHC | F10: ASHC | G10: UBER | H10: 4940.33 | I10: -38.4 | J10: 0 | K10: 0 | L10: -2048.73 | M10: =-98.8066+77 -> -21.8066 | N10: 0 | O10: =SUM(H10:N10) -> 2831.3934 | P10: -2142.85 | Q10: -375.31 | R10: -500 | S10: 0 | T10: 0 | U10: 0 | V10: 0 | W10: =+O10+SUM(P10:V10) -> -186.7666 | X10: =IF(W10>=0,W10,0) -> 0 | Y10: =IF(W10<=0,W10,0) -> -186.7666 | Z10: 187 | AA10: =+Y10+Z10 -> 0.2334 | AB10: =+O10-X10+Z10+AA10 -> 3018.6268
A11: 1 | B11: OSCAR BLANCAS NORIEGA | C11: VENTO|2017|GRIS|NZV7888 | D11: OHLM023720279 | E11: ASHC | F11: ASHC | G11: UBER | H11: 4068.3 | I11: -38.4 | J11: 0 | K11: 0 | L11: -935.09 | M11: =-81.366+77 -> -4.366 | N11: 0 | O11: =SUM(H11:N11) -> 3090.444 | P11: -1971.42 | Q11: -1063 | R11: -500 | S11: 0 | T11: 0 | U11: 0 | V11: 0 | W11: =+O11+SUM(P11:V11) -> -443.976 | X11: =IF(W11>=0,W11,0) -> 0 | Y11: =IF(W11<=0,W11,0) -> -443.976 | Z11: 444 | AA11: =+Y11+Z11 -> 0.024 | AB11: =+O11-X11+Z11+AA11 -> 3534.468
A12: 1 | B12: ULISES ITIEL CASTILLO AVILA | C12: KIA RIO|2020|GRIS|NCK475B | D12: OHLM031397326 | E12: ASHC | F12: IVETH | G12: UBER | H12: 5393.23 | I12: -68.8 | J12: 0 | K12: 0 | L12: -2447.29 | M12: -107.8646 | N12: 0 | O12: =SUM(H12:N12) -> 2769.2754 | P12: -2142.85 | Q12: 0 | R12: 0 | S12: 0 | T12: 0 | U12: 0 | V12: 0 | W12: =+O12+SUM(P12:V12) -> 626.4254 | X12: =IF(W12>=0,W12,0) -> 626.4254 | Y12: =IF(W12<=0,W12,0) -> 0 | Z12: 0 | AA12: =+Y12+Z12 -> 0 | AB12: =+O12-X12+Z12+AA12 -> 2142.85
A13: 2 | B13: ABRAHAM ESCOBEDO ESCALANTE | C13: BEAT|2020|GRIS|NFN014B | D13: - | E13: U64 | F13: ASHC | G13: UBER | H13: 1382.8 | I13: -22.4 | J13: 0 | K13: 0 | L13: -723.89 | M13: -27.656 | N13: 0 | O13: =SUM(H13:N13) -> 608.854 | P13: -1428.56 | Q13: 0 | R13: 0 | S13: 0 | T13: 0 | U13: 0 | V13: 0 | W13: =+O13+SUM(P13:V13) -> -819.706 | X13: =IF(W13>=0,W13,0) -> 0 | Y13: =IF(W13<=0,W13,0) -> -819.706 | Z13: 0 | AA13: =+Y13+Z13 -> -819.706 | AB13: =+O13-X13+Z13+AA13 -> -210.852 | AC13: PÉRDIDA
A14: 2 | B14: ADOLFO LOPEZ MARTINEZ | C14: AVEO|2021|OCRE|NEB156A | D14: OHLM023012552 | E14: ASHC | F14: IVETH | G14: UBER | H14: 0 | I14: 0 | J14: 0 | K14: 0 | L14: 0 | M14: 0 | N14: 0 | O14: =SUM(H14:N14) -> 0 | P14: -2500 | Q14: 0 | R14: 0 | S14: 0 | T14: 0 | U14: 0 | V14: 0 | W14: =+O14+SUM(P14:V14) -> -2500 | X14: =IF(W14>=0,W14,0) -> 0 | Y14: =IF(W14<=0,W14,0) -> -2500 | Z14: 2500 | AA14: =+Y14+Z14 -> 0 | AB14: =+O14-X14+Z14+AA14 -> 2500
A15: 2 | B15: ARACELI CASTILLO GUERRERO | C15: AVEO|2018|GRIS|X59AWG | D15: - | E15: ASHC | F15: ASHC | G15: UBER | H15: 3130.3 | I15: 0 | J15: 0 | K15: 0 | L15: -1220.45 | M15: -62.606 | N15: 0 | O15: =SUM(H15:N15) -> 1847.244 | P15: -2500 | Q15: 0 | R15: 0 | S15: 0 | T15: 0 | U15: 0 | V15: 0 | W15: =+O15+SUM(P15:V15) -> -652.756 | X15: =IF(W15>=0,W15,0) -> 0 | Y15: =IF(W15<=0,W15,0) -> -652.756 | Z15: 653 | AA15: =+Y15+Z15 -> 0.244 | AB15: =+O15-X15+Z15+AA15 -> 2500.488
A16: 2 | B16: CESAR PIÑA BARONA | C16: HYUNDAI|2022|PLATA|D40BKD | D16: OHLM023658024 | E16: ASHC | F16: IVETH | G16: UBER | H16: 0 | I16: 0 | J16: 0 | K16: 0 | L16: 0 | M16: 0 | N16: 0 | O16: =SUM(H16:N16) -> 0 | P16: -2500 | Q16: 0 | R16: 0 | S16: 0 | T16: 0 | U16: 0 | V16: 0 | W16: =+O16+SUM(P16:V16) -> -2500 | X16: =IF(W16>=0,W16,0) -> 0 | Y16: =IF(W16<=0,W16,0) -> -2500 | Z16: 2500 | AA16: =+Y16+Z16 -> 0 | AB16: =+O16-X16+Z16+AA16 -> 2500
A17: 2 | B17: CLAUDIA LEAÑOS | C17: KIA RIO|2017|ROJO|MYE912A | D17: - | E17: U64 | F17: ASHC | G17: UBER | H17: 3759.89 | I17: -60.8 | J17: 0 | K17: 0 | L17: -1578.07 | M17: -75.1978 | N17: 0 | O17: =SUM(H17:N17) -> 2045.8222 | P17: -2500 | Q17: 0 | R17: 0 | S17: 0 | T17: 0 | U17: 0 | V17: 0 | W17: =+O17+SUM(P17:V17) -> -454.1778 | X17: =IF(W17>=0,W17,0) -> 0 | Y17: =IF(W17<=0,W17,0) -> -454.1778 | Z17: 0 | AA17: =+Y17+Z17 -> -454.1778 | AB17: =+O17-X17+Z17+AA17 -> 1591.6444 | AC17: PÉRDIDA
A18: 2 | B18: DIEGO SANCHEZ | C18: VENTO|2020|GRIS|R66BER | D18: OHLM023720329 | E18: ASHC | F18: ASHC | G18: UBER | H18: 2574.35 | I18: 0 | J18: 0 | K18: 0 | L18: -1659.48 | M18: -51.487 | N18: 0 | O18: =SUM(H18:N18) -> 863.383 | P18: -1428.56 | Q18: 0 | R18: -500 | S18: 0 | T18: 0 | U18: 0 | V18: 0 | W18: =+O18+SUM(P18:V18) -> -1065.177 | X18: =IF(W18>=0,W18,0) -> 0 | Y18: =IF(W18<=0,W18,0) -> -1065.177 | Z18: 1065 | AA18: =+Y18+Z18 -> -0.177 | AB18: =+O18-X18+Z18+AA18 -> 1928.206
A19: 2 | B19: EDGAR GEOVANY URIBE | C19: AVEO|2019|PLATA|NEL860A | D19: OHLM023720337 | E19: ASHC | F19: ASHC | G19: UBER | H19: 4536.98 | I19: -119.2 | J19: 0 | K19: 0 | L19: -898.58 | M19: -113.3596 | N19: 0 | O19: =SUM(H19:N19) -> 3405.8404 | P19: -2500 | Q19: 0 | R19: 0 | S19: -500 | T19: 0 | U19: 0 | V19: 0 | W19: =+O19+SUM(P19:V19) -> 405.8404 | X19: =IF(W19>=0,W19,0) -> 405.8404 | Y19: =IF(W19<=0,W19,0) -> 0 | Z19: 0 | AA19: =+Y19+Z19 -> 0 | AB19: =+O19-X19+Z19+AA19 -> 3000
A20: 2 | B20: IRAM HERNANDEZ | C20: AVEO|2022|AZUL|MUF515A | D20: OHLM023720311 | E20: ASHC | F20: ASHC | G20: UBER | H20: 6165.24 | I20: 0 | J20: 0 | K20: 0 | L20: -2465.51 | M20: -123.3048 | N20: 0 | O20: =SUM(H20:N20) -> 3576.4252 | P20: -2500 | Q20: 0 | R20: 0 | S20: -500 | T20: 0 | U20: 0 | V20: 0 | W20: =+O20+SUM(P20:V20) -> 576.4252 | X20: =IF(W20>=0,W20,0) -> 576.4252 | Y20: =IF(W20<=0,W20,0) -> 0 | Z20: 0 | AA20: =+Y20+Z20 -> 0 | AB20: =+O20-X20+Z20+AA20 -> 3000
A21: 2 | B21: IVAN MOGUEL PULIDO | C21: VERSA|2023|PLATA|NCT814A | D21: OHLM023012487 | E21: ASHC | F21: ASHC | G21: UBER | H21: 11072.8 | I21: -262.4 | J21: 0 | K21: 0 | L21: -4296.05 | M21: -221.456 | N21: -46 | O21: =SUM(H21:N21) -> 6246.894 | P21: -2500 | Q21: 0 | R21: 0 | S21: 0 | T21: -500 | U21: 0 | V21: 0 | W21: =+O21+SUM(P21:V21) -> 3246.894 | X21: =IF(W21>=0,W21,0) -> 3246.894 | Y21: =IF(W21<=0,W21,0) -> 0 | Z21: 0 | AA21: =+Y21+Z21 -> 0 | AB21: =+O21-X21+Z21+AA21 -> 3000
A22: 2 | B22: JESUS AURELIO NUNGARAY CASTILLO | C22: VENTO|2020|GRIS|R66BER | D22: - | E22: ASHC | F22: ASHC | G22: UBER | H22: 2251.02 | I22: 0 | J22: 0 | K22: 0 | L22: -1814.27 | M22: -45.0204 | N22: -127.82 | O22: =SUM(H22:N22) -> 263.9096 | P22: -714.28 | Q22: 0 | R22: 0 | S22: 0 | T22: 0 | U22: 0 | V22: 0 | W22: =+O22+SUM(P22:V22) -> -450.3704 | X22: =IF(W22>=0,W22,0) -> 0 | Y22: =IF(W22<=0,W22,0) -> -450.3704 | Z22: 450 | AA22: =+Y22+Z22 -> -0.3704 | AB22: =+O22-X22+Z22+AA22 -> 713.5392
A23: 2 | B23: JORGE VAZQUEZ HERNANDEZ | C23: AVEO|2018|GRIS|X59AWG | D23: - | E23: ASHC | F23: ASHC | G23: UBER | H23: 3233.43 | I23: 0 | J23: 0 | K23: 0 | L23: -628.14 | M23: -64.6686 | N23: 0 | O23: =SUM(H23:N23) -> 2540.6214 | P23: -2500 | Q23: 0 | R23: 0 | S23: 0 | T23: 0 | U23: 0 | V23: 0 | W23: =+O23+SUM(P23:V23) -> 40.6214 | X23: =IF(W23>=0,W23,0) -> 40.6214 | Y23: =IF(W23<=0,W23,0) -> 0 | Z23: 0 | AA23: =+Y23+Z23 -> 0 | AB23: =+O23-X23+Z23+AA23 -> 2500
A24: 2 | B24: JOSE GUADALUPE GARCIA MORALES | C24: MARCH|2020|TURQ|N15BKD | D24: OHLM031409071 | E24: ASHC | F24: ASHC | G24: UBER | H24: 5208.21 | I24: 0 | J24: 0 | K24: 0 | L24: -3087.32 | M24: -104.1642 | N24: 0 | O24: =SUM(H24:N24) -> 2016.7258 | P24: -2500 | Q24: -1151.53 | R24: -500 | S24: 0 | T24: 0 | U24: 0 | V24: 0 | W24: =+O24+SUM(P24:V24) -> -2134.8042 | X24: =IF(W24>=0,W24,0) -> 0 | Y24: =IF(W24<=0,W24,0) -> -2134.8042 | Z24: 2135 | AA24: =+Y24+Z24 -> 0.1958 | AB24: =+O24-X24+Z24+AA24 -> 4151.9216
A25: 2 | B25: JOSE GUILLERMO HERNANDEZ RAMIREZ | C25: AVEO|2018|ROJO|R51BKD | D25: OHLM017365206 | E25: U64 | F25: ASHC | G25: UBER | H25: 6685.99 | I25: -164.8 | J25: 0 | K25: 0 | L25: -3647.5 | M25: -133.7198 | N25: 0 | O25: =SUM(H25:N25) -> 2739.9702 | P25: -2500 | Q25: 0 | R25: 0 | S25: 0 | T25: 0 | U25: 0 | V25: 0 | W25: =+O25+SUM(P25:V25) -> 239.9702 | X25: =IF(W25>=0,W25,0) -> 239.9702 | Y25: =IF(W25<=0,W25,0) -> 0 | Z25: 0 | AA25: =+Y25+Z25 -> 0 | AB25: =+O25-X25+Z25+AA25 -> 2500
A26: 2 | B26: JOSE JUAN HERNANDEZ MEJIA | C26: VERSA|2017|ACERO|X24APU | D26: OHLM023720345 | E26: ASHC | F26: ASHC | G26: UBER | H26: 3188.12 | I26: -48 | J26: 0 | K26: 0 | L26: -1867.2 | M26: -63.7624 | N26: 0 | O26: =SUM(H26:N26) -> 1209.1576 | P26: -2500 | Q26: -186.97 | R26: -500 | S26: 0 | T26: 0 | U26: 0 | V26: 0 | W26: =+O26+SUM(P26:V26) -> -1977.8124 | X26: =IF(W26>=0,W26,0) -> 0 | Y26: =IF(W26<=0,W26,0) -> -1977.8124 | Z26: 1882 | AA26: =+Y26+Z26 -> -95.8124 | AB26: =+O26-X26+Z26+AA26 -> 2995.3452
A27: 2 | B27: OSCAR BLANCAS NORIEGA | C27: VENTO|2017|GRIS|NZV7888 | D27: OHLM023720279 | E27: ASHC | F27: ASHC | G27: UBER | H27: 4151.87 | I27: -81.6 | J27: 0 | K27: 0 | L27: -1247.87 | M27: -83.0374 | N27: 0 | O27: =SUM(H27:N27) -> 2739.3626 | P27: -2300 | Q27: 0 | R27: -339 | S27: -257 | T27: 0 | U27: 0 | V27: 0 | W27: =+O27+SUM(P27:V27) -> -156.6374 | X27: =IF(W27>=0,W27,0) -> 0 | Y27: =IF(W27<=0,W27,0) -> -156.6374 | Z27: 157 | AA27: =+Y27+Z27 -> 0.3626 | AB27: =+O27-X27+Z27+AA27 -> 2896.7252
A28: 2 | B28: ULISES ITIEL CASTILLO AVILA | C28: KIA RIO|2020|GRIS|NCK475B | D28: OHLM031397326 | E28: ASHC | F28: IVETH | G28: UBER | H28: 7618.92 | I28: -139.2 | J28: 0 | K28: 0 | L28: -4430.72 | M28: -152.3784 | N28: 0 | O28: =SUM(H28:N28) -> 2896.6216 | P28: -2500 | Q28: 0 | R28: 0 | S28: 0 | T28: 0 | U28: 0 | V28: 0 | W28: =+O28+SUM(P28:V28) -> 396.6216 | X28: =IF(W28>=0,W28,0) -> 396.6216 | Y28: =IF(W28<=0,W28,0) -> 0 | Z28: 0 | AA28: =+Y28+Z28 -> 0 | AB28: =+O28-X28+Z28+AA28 -> 2500
A29: 3 | B29: ABRAHAM ESCOBEDO ESCALANTE | C29: BEAT|2020|GRIS|NFN014B | D29: - | E29: U64 | F29: ASHC | G29: UBER | H29: 2639.76 | I29: 0 | J29: 0 | K29: 0 | L29: -2186.24 | M29: -52.7952 | N29: 0 | O29: =SUM(H29:N29) -> 400.7248 | P29: -2500 | Q29: -35 | R29: 0 | S29: 0 | T29: 0 | U29: 0 | V29: 0 | W29: =+O29+SUM(P29:V29) -> -2134.2752 | X29: =IF(W29>=0,W29,0) -> 0 | Y29: =IF(W29<=0,W29,0) -> -2134.2752 | Z29: 0 | AA29: =+Y29+Z29 -> -2134.2752 | AB29: =+O29-X29+Z29+AA29 -> -1733.5504 | AC29: PÉRDIDA
A30: 3 | B30: ADOLFO LOPEZ MARTINEZ | C30: AVEO|2021|OCRE|NEB156A | D30: OHLM023012552 | E30: ASHC | F30: ASHC | G30: UBER | H30: 50.31 | I30: 0 | J30: 0 | K30: 0 | L30: 0 | M30: 0 | N30: 0 | O30: =SUM(H30:N30) -> 50.31 | P30: -1071 | Q30: 0 | R30: 0 | S30: 0 | T30: 0 | U30: 0 | V30: 0 | W30: =+O30+SUM(P30:V30) -> -1020.69 | X30: =IF(W30>=0,W30,0) -> 0 | Y30: =IF(W30<=0,W30,0) -> -1020.69 | Z30: 1021 | AA30: =+Y30+Z30 -> 0.31 | AB30: =+O30-X30+Z30+AA30 -> 1071.62
A31: 3 | B31: ADOLFO LOPEZ MARTINEZ | C31: AVEO|2021|OCRE|NEB156A | D31: OHLM023012552 | E31: ASHC | F31: IVETH | G31: UBER | H31: 1787.03 | I31: 0 | J31: 0 | K31: 0 | L31: -586.14 | M31: -35.7406 | N31: 0 | O31: =SUM(H31:N31) -> 1165.1494 | P31: -1429 | Q31: 0 | R31: 0 | S31: 0 | T31: 0 | U31: 0 | V31: 0 | W31: =+O31+SUM(P31:V31) -> -263.8506 | X31: =IF(W31>=0,W31,0) -> 0 | Y31: =IF(W31<=0,W31,0) -> -263.8506 | Z31: 264 | AA31: =+Y31+Z31 -> 0.1494 | AB31: =+O31-X31+Z31+AA31 -> 1429.2988
A32: 3 | B32: ARACELI CASTILLO GUERRERO | C32: AVEO|2018|GRIS|X59AWG | D32: - | E32: ASHC | F32: ASHC | G32: UBER | H32: 3737.75 | I32: 0 | J32: 0 | K32: 0 | L32: -1707.4 | M32: -74.755 | N32: 0 | O32: =SUM(H32:N32) -> 1955.595 | P32: -2500 | Q32: 0 | R32: 0 | S32: 0 | T32: 0 | U32: 0 | V32: 0 | W32: =+O32+SUM(P32:V32) -> -544.405 | X32: =IF(W32>=0,W32,0) -> 0 | Y32: =IF(W32<=0,W32,0) -> -544.405 | Z32: 544 | AA32: =+Y32+Z32 -> -0.405 | AB32: =+O32-X32+Z32+AA32 -> 2499.19
A33: 3 | B33: CESAR PIÑA BARONA | C33: HYUNDAI|2022|PLATA|D40BKD | D33: OHLM023658024 | E33: ASHC | F33: ASHC | G33: UBER | H33: 0 | I33: 0 | J33: 0 | K33: 0 | L33: 0 | M33: 0 | N33: 0 | O33: =SUM(H33:N33) -> 0 | P33: -1071 | Q33: -1300 | R33: 0 | S33: 0 | T33: 0 | U33: 0 | V33: 0 | W33: =+O33+SUM(P33:V33) -> -2371 | X33: =IF(W33>=0,W33,0) -> 0 | Y33: =IF(W33<=0,W33,0) -> -2371 | Z33: 2371 | AA33: =+Y33+Z33 -> 0 | AB33: =+O33-X33+Z33+AA33 -> 2371 | AC33: PAGADO
A34: 3 | B34: CESAR PIÑA BARONA | C34: HYUNDAI|2022|PLATA|D40BKD | D34: OHLM023658024 | E34: ASHC | F34: IVETH | G34: UBER | H34: 0 | I34: 0 | J34: 0 | K34: 0 | L34: 0 | M34: 0 | N34: 0 | O34: =SUM(H34:N34) -> 0 | P34: -1429 | Q34: 0 | R34: 0 | S34: 0 | T34: 0 | U34: 0 | V34: 0 | W34: =+O34+SUM(P34:V34) -> -1429 | X34: =IF(W34>=0,W34,0) -> 0 | Y34: =IF(W34<=0,W34,0) -> -1429 | Z34: 1429 | AA34: =+Y34+Z34 -> 0 | AB34: =+O34-X34+Z34+AA34 -> 1429 | AC34: PAGADO
A35: 3 | B35: CLAUDIA LEAÑOS | C35: KIA RIO|2017|ROJO|MYE912A | D35: - | E35: U64 | F35: ASHC | G35: UBER | H35: 449.82 | I35: 0 | J35: 0 | K35: 0 | L35: -93.56 | M35: 0 | N35: 0 | O35: =SUM(H35:N35) -> 356.26 | P35: 0 | Q35: 0 | R35: 0 | S35: 0 | T35: 0 | U35: 0 | V35: 0 | W35: =+O35+SUM(P35:V35) -> 356.26 | X35: =IF(W35>=0,W35,0) -> 356.26 | Y35: =IF(W35<=0,W35,0) -> 0 | Z35: 0 | AA35: =+Y35+Z35 -> 0 | AB35: =+O35-X35+Z35+AA35 -> 0
A36: 3 | B36: DIEGO SANCHEZ | C36: VENTO|2020|GRIS|R66BER | D36: OHLM023720329 | E36: ASHC | F36: ASHC | G36: UBER | H36: 4532.44 | I36: 0 | J36: 0 | K36: 0 | L36: -2041.45 | M36: -101.0688 | N36: 0 | O36: =SUM(H36:N36) -> 2389.9212 | P36: -2500 | Q36: 0 | R36: -500 | S36: 0 | T36: 0 | U36: 0 | V36: 0 | W36: =+O36+SUM(P36:V36) -> -610.0788 | X36: =IF(W36>=0,W36,0) -> 0 | Y36: =IF(W36<=0,W36,0) -> -610.0788 | Z36: 620 | AA36: =+Y36+Z36 -> 9.9212 | AB36: =+O36-X36+Z36+AA36 -> 3019.8424 | AC36: PAGADO | 21 ENE
A37: 3 | B37: EDGAR GEOVANY URIBE | C37: AVEO|2019|PLATA|NEL860A | D37: OHLM023720337 | E37: ASHC | F37: ASHC | G37: UBER | H37: 5544.83 | I37: -101.6 | J37: 0 | K37: 0 | L37: -1756.2 | M37: -137.71245 | N37: 0 | O37: =SUM(H37:N37) -> 3549.3175 | P37: -2500 | Q37: 0 | R37: 0 | S37: -500 | T37: 0 | U37: 0 | V37: 0 | W37: =+O37+SUM(P37:V37) -> 549.31755 | X37: =IF(W37>=0,W37,0) -> 549.31755 | Y37: =IF(W37<=0,W37,0) -> 0 | Z37: 0 | AA37: =+Y37+Z37 -> 0 | AB37: =+O37-X37+Z37+AA37 -> 3000
A38: 3 | B38: FERNANDO ESQUIVEL SOSA | C38: VENTO|2018|AMARILLO|PED1652 | D38: OHLM031409055 | E38: ASHC | F38: ASHC | G38: UBER | H38: 7403.76 | I38: -138.4 | J38: 0 | K38: 0 | L38: -1056.42 | M38: -148.0752 | N38: 0 | O38: =SUM(H38:N38) -> 6060.8648 | P38: -1968 | Q38: 0 | R38: -500 | S38: 0 | T38: 0 | U38: 0 | V38: 0 | W38: =+O38+SUM(P38:V38) -> 3592.8648 | X38: =IF(W38>=0,W38,0) -> 3592.8648 | Y38: =IF(W38<=0,W38,0) -> 0 | Z38: 0 | AA38: =+Y38+Z38 -> 0 | AB38: =+O38-X38+Z38+AA38 -> 2468
A39: 3 | B39: IRAM HERNANDEZ | C39: AVEO|2022|AZUL|MUF515A | D39: OHLM023720311 | E39: ASHC | F39: ASHC | G39: UBER | H39: 5136.53 | I39: -54.31 | J39: 0 | K39: 0 | L39: -1437.61 | M39: -77.04795 | N39: -55 | O39: =SUM(H39:N39) -> 3512.562 | P39: -2500 | Q39: 0 | R39: 0 | S39: -300 | T39: 0 | U39: 0 | V39: 0 | W39: =+O39+SUM(P39:V39) -> 712.56205 | X39: =IF(W39>=0,W39,0) -> 712.56205 | Y39: =IF(W39<=0,W39,0) -> 0 | Z39: 0 | AA39: =+Y39+Z39 -> 0 | AB39: =+O39-X39+Z39+AA39 -> 2800
A40: 3 | B40: IVAN MOGUEL PULIDO | C40: VERSA|2023|PLATA|NCT814A | D40: OHLM023012487 | E40: ASHC | F40: ASHC | G40: UBER | H40: 9859.83 | I40: -121.6 | J40: 0 | K40: 0 | L40: -4486.28 | M40: -197.1966 | N40: -217.97 | O40: =SUM(H40:N40) -> 4836.7834 | P40: -2500 | Q40: -1500 | R40: 0 | S40: 0 | T40: -500 | U40: 0 | V40: 0 | W40: =+O40+SUM(P40:V40) -> 336.7834 | X40: =IF(W40>=0,W40,0) -> 336.7834 | Y40: =IF(W40<=0,W40,0) -> 0 | Z40: 0 | AA40: =+Y40+Z40 -> 0 | AB40: =+O40-X40+Z40+AA40 -> 4500
...

Sheet UBER 2026
A1: SEM | B1: CONDUCTOR | C1: LLAVE | D1: TAG | E1: SOCIO | F1: PLATAFORMA | G1: APP | H1: GANANCIA | I1: EFECTIVO | J1: IMPUESTOS | K1: P. A ANT | L1: SEGURO | M1: P T | N1: TAG | O1: UBERG | P1: RENTA | Q1: SEM A | R1: FIANZA | S1: MULTA | T1: HOJALAT | U1: DESC | V1: PRÉST | W1: TOTAL | X1: A PAGAR | Y1: DEV | Z1: PAGADO | AA1: ADEUDO | AB1: GANAN T | AC1: ANT F | AD1: COMENTARIOS
A2: 1 | B2: ALEJANDRO PAZ CAMACHO | C2: MARCH|2020|TURQ|N15BKD | D2: OHLM038285789 | E2: ASHC | F2: ASHC | G2: DIDI | H2: 4784.74 | I2: -6209.03 | J2: -620 | K2: 0 | L2: 0 | M2: -95 | N2: 0 | O2: =IF(H2+I2<0,SUM(J2:N2),SUM(H2:N2)) -> -715 | P2: -2600 | Q2: -2771.97 | R2: 0 | S2: 0 | T2: 0 | U2: 0 | V2: 0 | W2: =SUM(O2:V2) -> -6086.97 | X2: =IF(W2>=0,W2,0) -> 0 | Y2: =IF(W2<=0,W2,0) -> -6086.97 | Z2: =800+2357 -> 3157 | AA2: =+Y2+Z2 -> -2929.97 | AB2: =+O2-X2+Z2+AA2 -> -487.97 | AD2: SE CONDONA ADEUDO Y SE AJUSTA DEUDO 2025 | AG2: preguntar si pago 2352
A3: 1 | B3: RAUL FRANCISCO VAZQUEZ CORTE | C3: V DRIVE|2023|GRIS|MXW453C | D3: OHLM038626776 | E3: ASHC | F3: ASHC | G3: DIDI | H3: 176.49 | I3: -130.25 | J3: -13 | K3: 0 | L3: 0 | M3: -65 | N3: 0 | O3: =IF(H3+I3<0,SUM(J3:N3),SUM(H3:N3)) -> -31.76 | P3: -2500 | Q3: -94 | R3: 0 | S3: 0 | T3: -500 | U3: 0 | V3: 0 | W3: =SUM(O3:V3) -> -3125.76 | X3: =IF(W3>=0,W3,0) -> 0 | Y3: =IF(W3<=0,W3,0) -> -3125.76 | Z3: 2800 | AA3: =+Y3+Z3 -> -325.76 | AB3: =+O3-X3+Z3+AA3 -> 2442.48 | AD3: DA RENTA POR FUERA HOJALATERIA 11/18, PAGA 2,800 11 ENE
A4: 1 | B4: FRANCISCO RODOLFO GOMEZ URQUIZA ESCALANTE | C4: KIA RIO|2020|AZUL|LUE960C | D4: OHLM035935635 | E4: ASHC | F4: ASHC | G4: DIDI | H4: 2721.77 | I4: -2373.6 | J4: -237 | K4: 0 | L4: 0 | M4: -95 | N4: 0 | O4: =IF(H4+I4<0,SUM(J4:N4),SUM(H4:N4)) -> 16.17 | P4: -2600 | Q4: 0 | R4: 0 | S4: 0 | T4: 0 | U4: 0 | V4: 0 | W4: =SUM(O4:V4) -> -2583.83 | X4: =IF(W4>=0,W4,0) -> 0 | Y4: =IF(W4<=0,W4,0) -> -2583.83 | Z4: 2857 | AA4: =+Y4+Z4 -> 273.17 | AB4: =+O4-X4+Z4+AA4 -> 3146.34 | AD4: TRABAJA DIDI-ASHC, PAGO 2,857 10 ENE (273 DE DIDI ATRASOS)
A5: 1 | B5: FRANCISCO ISLAS CHAVEZ | C5: AVEO|2024|GRIS|LRL009C | D5: OHLM032762171 | E5: ASHC | F5: ASHC | G5: DIDI | H5: 5249.01 | I5: -6142.27 | J5: -614 | K5: 0 | L5: 0 | M5: -95 | N5: 0 | O5: =IF(H5+I5<0,SUM(J5:N5),SUM(H5:N5)) -> -709 | P5: -2600 | Q5: 0 | R5: 0 | S5: 0 | T5: 0 | U5: 0 | V5: 0 | W5: =SUM(O5:V5) -> -3309 | X5: =IF(W5>=0,W5,0) -> 0 | Y5: =IF(W5<=0,W5,0) -> -3309 | Z5: =1200+1000 -> 2200 | AA5: =+Y5+Z5 -> -1109 | AB5: =+O5-X5+Z5+AA5 -> 382 | AD5: TRABAJA AMBAS APPS | PAGO 7 ENE 1,200 + 1,000 10 ENE GESTIONAR PAGO URGE
A6: 1 | B6: ADALBERTO BELLO NAVARRO | C6: AVEO|2025|PERSUASION|MXM510C | D6: OHLM038285821 | E6: ASHC | F6: ASHC | G6: UBER | H6: 8443.13 | I6: -5565.59 | J6: -20.8 | K6: 0 | L6: 0 | M6: -60 | N6: 0 | O6: =IF(H6+I6<0,SUM(J6:N6),SUM(H6:N6)) -> 2796.74 | P6: -2700 | Q6: 0 | R6: 0 | S6: 0 | T6: 0 | U6: 0 | V6: 0 | W6: =SUM(O6:V6) -> 96.74 | X6: =IF(W6>=0,W6,0) -> 96.74 | Y6: =IF(W6<=0,W6,0) -> 0 | Z6: 0 | AA6: =+Y6+Z6 -> 0 | AB6: =+O6-X6+Z6+AA6 -> 2700
A7: 1 | B7: ADRIAN CRUZ CUADROS | C7: AVEO|2025|PERSUASION|MXM503C | D7: OHLM038285813 | E7: ASHC | F7: ASHC | G7: UBER | H7: 6903.68 | I7: 0 | J7: -66.72 | K7: 19.58 | L7: 0 | M7: -77 | N7: -89 | O7: =IF(H7+I7<0,SUM(J7:N7),SUM(H7:N7)) -> 6690.54 | P7: -2700 | Q7: 0 | R7: 0 | S7: 0 | T7: 0 | U7: 0 | V7: 0 | W7: =SUM(O7:V7) -> 3990.54 | X7: =IF(W7>=0,W7,0) -> 3990.54 | Y7: =IF(W7<=0,W7,0) -> 0 | Z7: 0 | AA7: =+Y7+Z7 -> 0 | AB7: =+O7-X7+Z7+AA7 -> 2700
A8: 1 | B8: ALBERTO ARRIAGA MEJIA | C8: AVEO|2020|AZUL|D28BET | D8: OHLM032370140 | E8: ASHC | F8: ASHC | G8: UBER | H8: 1020.36 | I8: -59.93 | J8: -11.2 | K8: 0 | L8: 0 | M8: -63 | N8: -71 | O8: =IF(H8+I8<0,SUM(J8:N8),SUM(H8:N8)) -> 815.23 | P8: -2500 | Q8: 0 | R8: -500 | S8: 0 | T8: 0 | U8: 0 | V8: 0 | W8: =SUM(O8:V8) -> -2184.77 | X8: =IF(W8>=0,W8,0) -> 0 | Y8: =IF(W8<=0,W8,0) -> -2184.77 | Z8: =1100+1085 -> 2185 | AA8: =+Y8+Z8 -> 0.23 | AB8: =+O8-X8+Z8+AA8 -> 3000.46 | AD8: FIANZA 7/11 PAGO 7 ENE 1,100 + 1,085 8 ENE
A9: 1 | B9: ANGEL ALCANTARA CRUZ | C9: AVEO|2025|PERSUASION|MZN091C | D9: OHLM038626768 | E9: ASHC | F9: ASHC | G9: UBER | H9: 668.17 | I9: -29.99 | J9: -4.48 | K9: 0 | L9: 0 | M9: -60 | N9: 0 | O9: =IF(H9+I9<0,SUM(J9:N9),SUM(H9:N9)) -> 573.7 | P9: 0 | Q9: -737 | R9: 0 | S9: 0 | T9: 0 | U9: 0 | V9: 0 | W9: =SUM(O9:V9) -> -163.3 | X9: =IF(W9>=0,W9,0) -> 0 | Y9: =IF(W9<=0,W9,0) -> -163.3 | Z9: 0 | AA9: =+Y9+Z9 -> -163.3 | AB9: =+O9-X9+Z9+AA9 -> 410.4 | AD9: ADEUDO SEM ANT - PROB FAM HIJA LEUSEM PAGA EL LUNES SE CONDONA LA CUENTA
A10: 1 | B10: ARMANDO MARTINEZ VELAZQUEZ | C10: HYUNDAI|2022|PLATA|D40BKD | D10: OHLM023658024 | E10: ASHC | F10: ASHC | G10: UBER | H10: 922.84 | I10: 0 | J10: -4.48 | K10: 0 | L10: -8.49 | M10: -60 | N10: 0 | O10: =IF(H10+I10<0,SUM(J10:N10),SUM(H10:N10)) -> 849.87 | P10: -357.14286 | Q10: 0 | R10: 0 | S10: 0 | T10: -600 | U10: 0 | V10: 0 | W10: =SUM(O10:V10) -> -107.27286 | X10: =IF(W10>=0,W10,0) -> 0 | Y10: =IF(W10<=0,W10,0) -> -107.27286 | Z10: 0 | AA10: =+Y10+Z10 -> -107.27286 | AB10: =+O10-X10+Z10+AA10 -> 742.59714 | AD10: HOJALATERIA 2/5 PAGA HASTA LA SEM 3 SIN DESC DE HOJ
A11: 1 | B11: CAMILO IESUA MEJIA DIAZ | C11: KIA RIO|2020|GRIS|NCK475B | D11: OHLM032370124 | E11: ASHC | F11: ASHC | G11: UBER | H11: 2560.11 | I11: -491.67 | J11: -16.96 | K11: 106.1 | L11: 0 | M11: -60 | N11: 0 | O11: =IF(H11+I11<0,SUM(J11:N11),SUM(H11:N11)) -> 2097.58 | P11: -2500 | Q11: 0 | R11: -500 | S11: 0 | T11: 0 | U11: 0 | V11: 0 | W11: =SUM(O11:V11) -> -902.42 | X11: =IF(W11>=0,W11,0) -> 0 | Y11: =IF(W11<=0,W11,0) -> -902.42 | Z11: 902 | AA11: =+Y11+Z11 -> -0.42 | AB11: =+O11-X11+Z11+AA11 -> 2999.16 | AD11: FIANZA 5/10 PAGO 7 ENE 902
A12: 1 | B12: DAVID ARTURO GONZALEZ TELLEZ | C12: AVEO|2025|PERSUASION|MXM502C | D12: OHLM038285805 | E12: ASHC | F12: ASHC | G12: UBER | H12: 1605.6 | I12: -1702.64 | J12: -9.44 | K12: 0 | L12: 0 | M12: -86 | N12: -125.49 | O12: =IF(H12+I12<0,SUM(J12:N12),SUM(H12:N12)) -> -220.93 | P12: -771.42 | Q12: -4976 | R12: 0 | S12: 0 | T12: -700 | U12: 0 | V12: 0 | W12: =SUM(O12:V12) -> -6668.35 | X12: =IF(W12>=0,W12,0) -> 0 | Y12: =IF(W12<=0,W12,0) -> -6668.35 | Z12: =1000+1300+1000 -> 3300 | AA12: =+Y12+Z12 -> -3368.35 | AB12: =+O12-X12+Z12+AA12 -> -289.28 | AD12: CTA PROP 2 DIAS PQ SALIO CDMX,HOJALATERIA 11/26 - 1,300 9 ENE + 1,000 11 ENE 8ene 1000
A13: 1 | B13: FERNANDO FUENTES OTERO | C13: AVEOH|2024|BLANCO|MWV156C | D13: OHLM038626743 | E13: ASHC | F13: ASHC | G13: UBER | H13: 309.82 | I13: 0 | J13: 0 | K13: 0 | L13: 0 | M13: -60 | N13: 0 | O13: =IF(H13+I13<0,SUM(J13:N13),SUM(H13:N13)) -> 249.82 | P13: -2500 | Q13: -250 | R13: 0 | S13: 0 | T13: 0 | U13: 0 | V13: 0 | W13: =SUM(O13:V13) -> -2500.18 | X13: =IF(W13>=0,W13,0) -> 0 | Y13: =IF(W13<=0,W13,0) -> -2500.18 | Z13: =610+473+375+400+500+306 -> 2664 | AA13: =+Y13+Z13 -> 163.82 | AB13: =+O13-X13+Z13+AA13 -> 3077.64 | AD13: PAGO TRANSF ASHC 5 ENE 610, 473 9 ENE, 375 10 ENE, 400 10 ENE, 500 11 ENE, 306 11 ENE
A14: 1 | B14: FRANCISCO GOMEZ URQUIZA SILVA | C14: VERSA|2023|PLATA|NCT814A | D14: OHLM031491780 | E14: ASHC | F14: ASHC | G14: UBER | H14: 4543.72 | I14: -2246.92 | J14: -31.84 | K14: 0 | L14: 0 | M14: -65 | N14: 0 | O14: =IF(H14+I14<0,SUM(J14:N14),SUM(H14:N14)) -> 2199.96 | P14: -2500 | Q14: 0 | R14: -500 | S14: 0 | T14: 0 | U14: 0 | V14: 0 | W14: =SUM(O14:V14) -> -800.04 | X14: =IF(W14>=0,W14,0) -> 0 | Y14: =IF(W14<=0,W14,0) -> -800.04 | Z14: 800 | AA14: =+Y14+Z14 -> -0.04 | AB14: =+O14-X14+Z14+AA14 -> 2999.92 | AD14: FIANZA 5/10 - PAGO 800 6 ENE
A15: 1 | B15: FRANCISCO ISLAS CHAVEZ | C15: AVEO|2024|GRIS|LRL009C | D15: OHLM032762171 | E15: ASHC | F15: ASHC | G15: UBER | H15: 95.23 | I15: -80.21 | J15: 0 | K15: 0 | L15: 0 | M15: -15 | N15: 0 | O15: =IF(H15+I15<0,SUM(J15:N15),SUM(H15:N15)) -> 0.02 | P15: 0 | Q15: 0 | R15: 0 | S15: 0 | T15: 0 | U15: 0 | V15: 0 | W15: =SUM(O15:V15) -> 0.02 | X15: =IF(W15>=0,W15,0) -> 0.02 | Y15: =IF(W15<=0,W15,0) -> 0 | Z15: 0 | AA15: =+Y15+Z15 -> 0 | AB15: =+O15-X15+Z15+AA15 -> 0 | AD15: SE COBRA CTA COMPL EN DIDI
A16: 1 | B16: GERMAN LUSARRETA ROMERO | C16: AVEO|2021|GRIS|D51BHV | D16: OHLM037480324 | E16: ASHC | F16: ASHC | G16: UBER | H16: 5101.6 | I16: -1716.25 | J16: -23.84 | K16: 311.99 | L16: 0 | M16: -66.5 | N16: -25.87 | O16: =IF(H16+I16<0,SUM(J16:N16),SUM(H16:N16)) -> 3581.13 | P16: -2500 | Q16: 0 | R16: -500 | S16: 0 | T16: 0 | U16: 0 | V16: 0 | W16: =SUM(O16:V16) -> 581.13 | X16: =IF(W16>=0,W16,0) -> 581.13 | Y16: =IF(W16<=0,W16,0) -> 0 | Z16: 0 | AA16: =+Y16+Z16 -> 0 | AB16: =+O16-X16+Z16+AA16 -> 3000 | AD16: FIANZA 6/11
A17: 1 | B17: JESUS ROSALES GARCIA | C17: AVEOH|2026|ACERO|NEJ996C | D17: SIN TAG | E17: ASHC | F17: ASHC | G17: UBER | H17: 10752.02 | I17: -5054.19 | J17: -36.48 | K17: 0 | L17: 0 | M17: -65 | N17: 0 | O17: =IF(H17+I17<0,SUM(J17:N17),SUM(H17:N17)) -> 5596.35 | P17: =-357.14-2314.28 -> -2671.42 | Q17: 0 | R17: -500 | S17: 0 | T17: 0 | U17: 0 | V17: 0 | W17: =SUM(O17:V17) -> 2424.93 | X17: =IF(W17>=0,W17,0) -> 2424.93 | Y17: =IF(W17<=0,W17,0) -> 0 | Z17: 0 | AA17: =+Y17+Z17 -> 0 | AB17: =+O17-X17+Z17+AA17 -> 3171.42 | AD17: CTA PROPDEL LUNES 2,500, RESTO DE SEM 2700
A18: 1 | B18: JONATHAN BERNAL RODRIGUEZ | C18: AVEO|2018|GRIS|X59AWG | D18: OHLM031409063 | E18: ASHC | F18: ASHC | G18: UBER | H18: 2245.26 | I18: -363.75 | J18: 0 | K18: 0 | L18: -24.09 | M18: -140 | N18: -378.18 | O18: =IF(H18+I18<0,SUM(J18:N18),SUM(H18:N18)) -> 1339.24 | P18: -2500 | Q18: -627 | R18: -500 | S18: 0 | T18: 0 | U18: 0 | V18: 0 | W18: =SUM(O18:V18) -> -2287.76 | X18: =IF(W18>=0,W18,0) -> 0 | Y18: =IF(W18<=0,W18,0) -> -2287.76 | Z18: 1800 | AA18: =+Y18+Z18 -> -487.76 | AB18: =+O18-X18+Z18+AA18 -> 2651.48 | AD18: PAGA 1,800 10 ENE
A19: 1 | B19: JOSE GUILLERMO HERNANDEZ RAMIREZ | C19: AVEO|2023|GRIS|MLC126A | D19: OHLM037480332 | E19: ASHC | F19: ASHC | G19: UBER | H19: 7594.7 | I19: -3449.65 | J19: -36.48 | K19: 0 | L19: 0 | M19: -65 | N19: 0 | O19: =IF(H19+I19<0,SUM(J19:N19),SUM(H19:N19)) -> 4043.57 | P19: -1250 | Q19: -360 | R19: 0 | S19: 0 | T19: 0 | U19: 0 | V19: 0 | W19: =SUM(O19:V19) -> 2433.57 | X19: =IF(W19>=0,W19,0) -> 2433.57 | Y19: =IF(W19<=0,W19,0) -> 0 | Z19: 0 | AA19: =+Y19+Z19 -> 0 | AB19: =+O19-X19+Z19+AA19 -> 1610 | AD19: REDUCCION DE CTA 1/2
A20: 1 | B20: JOSE JUAN HERNANDEZ MEJIA | C20: VENTO|2020|GRIS|A19BDY | D20: OHLM038626750 | E20: ASHC | F20: ASHC | G20: UBER | H20: 7690.57 | I20: -3610.68 | J20: -76.96 | K20: 0 | L20: 0 | M20: -65 | N20: 0 | O20: =IF(H20+I20<0,SUM(J20:N20),SUM(H20:N20)) -> 3937.93 | P20: -2500 | Q20: -210 | R20: 0 | S20: 0 | T20: 0 | U20: 0 | V20: 0 | W20: =SUM(O20:V20) -> 1227.93 | X20: =IF(W20>=0,W20,0) -> 1227.93 | Y20: =IF(W20<=0,W20,0) -> 0 | Z20: 0 | AA20: =+Y20+Z20 -> 0 | AB20: =+O20-X20+Z20+AA20 -> 2710
A21: 1 | B21: JUAN CARLOS ZEA CRUZ | C21: AVEO|2019|PLATA|NEL860A | D21: OHLM032370132 | E21: ASHC | F21: ASHC | G21: UBER | H21: 2373.01 | I21: -218.08 | J21: 0 | K21: 0 | L21: 0 | M21: -60 | N21: 0 | O21: =IF(H21+I21<0,SUM(J21:N21),SUM(H21:N21)) -> 2094.93 | P21: -2500 | Q21: 0 | R21: -500 | S21: 0 | T21: 0 | U21: 0 | V21: 0 | W21: =SUM(O21:V21) -> -905.07 | X21: =IF(W21>=0,W21,0) -> 0 | Y21: =IF(W21<=0,W21,0) -> -905.07 | Z21: 605 | AA21: =+Y21+Z21 -> -300.07 | AB21: =+O21-X21+Z21+AA21 -> 2399.86 | AD21: FIANZA 3/11 PAGO 7 ENE 605 NO CONTESTA
A22: 1 | B22: KRISTOPHER ALEXANDER TORREALBA RAMOS | C22: VENTO|2017|GRIS|MMA672C | D22: OHLM023720279 | E22: ASHC | F22: ASHC | G22: UBER | H22: 3703.3 | I22: -2282.87 | J22: 0 | K22: 0 | L22: 0 | M22: -60 | N22: 0 | O22: =IF(H22+I22<0,SUM(J22:N22),SUM(H22:N22)) -> 1360.43 | P22: -1360 | Q22: 0 | R22: 0 | S22: 0 | T22: 0 | U22: 0 | V22: 0 | W22: =SUM(O22:V22) -> 0.43 | X22: =IF(W22>=0,W22,0) -> 0.43 | Y22: =IF(W22<=0,W22,0) -> 0 | Z22: 0 | AA22: =+Y22+Z22 -> 0 | AB22: =+O22-X22+Z22+AA22 -> 1360 | AD22: CTA PROPAL JUEVES, ABANDONA AUTO, NO SE LE REGRESA FIANZA NI PAGO.
A23: 1 | B23: MARCO ANTONIO FARIAS AVILES | C23: BEAT|2019|OCRE|MAY730C | D23: OHLM036759058 | E23: U64 | F23: ASHC | G23: UBER | H23: 1577.88 | I23: 0 | J23: -9.28 | K23: 0 | L23: 0 | M23: -65 | N23: 0 | O23: =IF(H23+I23<0,SUM(J23:N23),SUM(H23:N23)) -> 1503.6 | P23: -2500 | Q23: -76 | R23: -500 | S23: 0 | T23: 0 | U23: 0 | V23: 0 | W23: =SUM(O23:V23) -> -1572.4 | X23: =IF(W23>=0,W23,0) -> 0 | Y23: =IF(W23<=0,W23,0) -> -1572.4 | Z23: =1000+500 -> 1500 | AA23: =+Y23+Z23 -> -72.4 | AB23: =+O23-X23+Z23+AA23 -> 2931.2 | AD23: FIANZA 3/10 PAGO 7 ENE 1,000 Y 500 11 ENE
A24: 1 | B24: OSCAR BLANCAS NORIEGA | C24: VENTO|2020|GRIS|R66BER | D24: OHLM023720329 | E24: ASHC | F24: ASHC | G24: UBER | H24: 2073.67 | I24: -619.58 | J24: -14.4 | K24: 0 | L24: 0 | M24: -11 | N24: 0 | O24: =IF(H24+I24<0,SUM(J24:N24),SUM(H24:N24)) -> 1428.69 | P24: -1428.57 | Q24: 0 | R24: 0 | S24: 0 | T24: 0 | U24: 0 | V24: 0 | W24: =SUM(O24:V24) -> 0.12 | X24: =IF(W24>=0,W24,0) -> 0.12 | Y24: =IF(W24<=0,W24,0) -> 0 | Z24: 0 | AA24: =+Y24+Z24 -> 0 | AB24: =+O24-X24+Z24+AA24 -> 1428.57 | AD24: CTA PROP 4 DÍAS, SE BAJA VIE, ADEUDA HOJTRIA, LLAVE, Y LAV INTER (SIN DEV DE FIANZA)
A25: 1 | B25: RAYMUNDO CHAVEZ DELGADO | C25: AVEOH|2026|ACERO|NEJ971C | D25: SIN TAG | E25: ASHC | F25: ASHC | G25: UBER | H25: 3451.27 | I25: -1775.14 | J25: -16.96 | K25: 127.04 | L25: -42.97 | M25: -65 | N25: 0 | O25: =IF(H25+I25<0,SUM(J25:N25),SUM(H25:N25)) -> 1678.24 | P25: =-357.14-2314.28 -> -2671.42 | Q25: 0 | R25: -500 | S25: 0 | T25: 0 | U25: 0 | V25: 0 | W25: =SUM(O25:V25) -> -1493.18 | X25: =IF(W25>=0,W25,0) -> 0 | Y25: =IF(W25<=0,W25,0) -> -1493.18 | Z25: 0 | AA25: =+Y25+Z25 -> -1493.18 | AB25: =+O25-X25+Z25+AA25 -> 185.06 | AD25: CTA LUNES 2,500, MAR-DOM 2700, FIANZA 10/10 - QUEDA CON ROUS PAGO EN DOS EXHIBISIONES S2 746.5 Y S3 746.5 +12%
A26: 1 | B26: RICARDO HERNANDEZ ARIAS | C26: AVEO|2019|BLANCO|NBS225A | D26: OHLM038285797 | E26: ASHC | F26: ASHC | G26: UBER | H26: 7279.62 | I26: -277.08 | J26: -42.02 | K26: -5.32 | L26: 0 | M26: -65 | N26: 0 | O26: =IF(H26+I26<0,SUM(J26:N26),SUM(H26:N26)) -> 6890.2 | P26: -2500 | Q26: 0 | R26: 0 | S26: 0 | T26: -700 | U26: 0 | V26: 0 | W26: =SUM(O26:V26) -> 3690.2 | X26: =IF(W26>=0,W26,0) -> 3690.2 | Y26: =IF(W26<=0,W26,0) -> 0 | Z26: 0 | AA26: =+Y26+Z26 -> 0 | AB26: =+O26-X26+Z26+AA26 -> 3200 | AD26: HOJALATERIA 11/23
A27: 1 | B27: SAUL DOMINGUEZ VAZQUEZ | C27: VERSA|2020|BLANCO|A35BHD | D27: OHLM032370082 | E27: ASHC | F27: ASHC | G27: UBER | H27: 2853.66 | I27: -428.05 | J27: -34.56 | K27: 0 | L27: -23.35 | M27: -60 | N27: 0 | O27: =IF(H27+I27<0,SUM(J27:N27),SUM(H27:N27)) -> 2307.7 | P27: -2500 | Q27: 0 | R27: 0 | S27: 0 | T27: 0 | U27: 0 | V27: 0 | W27: =SUM(O27:V27) -> -192.3 | X27: =IF(W27>=0,W27,0) -> 0 | Y27: =IF(W27<=0,W27,0) -> -192.3 | Z27: 192 | AA27: =+Y27+Z27 -> -0.3 | AB27: =+O27-X27+Z27+AA27 -> 2499.4 | AD27: PAGA 192 6 ENE
A28: 1 | B28: SERGIO BALDERAS BAEZ | C28: AVEO|2022|AZUL|NZY685B | D28: OHLM032370116 | E28: ASHC | F28: ASHC | G28: UBER | H28: 5549.21 | I28: -1856.39 | J28: -18.88 | K28: 0 | L28: 0 | M28: -65 | N28: 0 | O28: =IF(H28+I28<0,SUM(J28:N28),SUM(H28:N28)) -> 3608.94 | P28: -2500 | Q28: 0 | R28: -500 | S28: 0 | T28: 0 | U28: -1000 | V28: 0 | W28: =SUM(O28:V28) -> -391.06 | X28: =IF(W28>=0,W28,0) -> 0 | Y28: =IF(W28<=0,W28,0) -> -391.06 | Z28: 391 | AA28: =+Y28+Z28 -> -0.06 | AB28: =+O28-X28+Z28+AA28 -> 3999.88 | AD28: FIANZA 7/10, PAGA ADEUDO 2/2 | PAGO 7 ENE 391
A29: 1 | B29: YOSHUA JARETH VALDEZ HERNANDEZ | C29: KIA RIO|2017|ROJO|MYE912A | D29: OHLM032762130 | E29: U64 | F29: BYER | G29: UBER | H29: 1169.28 | I29: -370.52 | J29: -4.48 | K29: 0 | L29: 0 | M29: -65 | N29: 0 | O29: =IF(H29+I29<0,SUM(J29:N29),SUM(H29:N29)) -> 729.28 | P29: -2500 | Q29: 871 | R29: 0 | S29: 0 | T29: 0 | U29: 0 | V29: 0 | W29: =SUM(O29:V29) -> -899.72 | X29: =IF(W29>=0,W29,0) -> 0 | Y29: =IF(W29<=0,W29,0) -> -899.72 | Z29: 900 | AA29: =+Y29+Z29 -> 0.28 | AB29: =+O29-X29+Z29+AA29 -> 1629.56 | AD29: SEM 817 A FAVOR, ADEUDO DE GOLPE 2018, $5000 SEMANALES - DEPOSITA 3,000 6 ENE (900 A CUENTA Y 2,100 GLPE PED)
A30: 1 | B30: JOSE AGUILAR SOTO | C30: AVEO|2020|AZUL|D28BET | D30: OHLM032370140 | E30: ASHC | F30: ASHC | G30: UBER | H30: 0 | I30: 0 | J30: 0 | K30: 0 | L30: 0 | M30: 0 | N30: 0 | O30: =IF(H30+I30<0,SUM(J30:N30),SUM(H30:N30)) -> 0 | P30: 0 | Q30: 0 | R30: 500 | S30: 0 | T30: 0 | U30: 0 | V30: 0 | W30: =SUM(O30:V30) -> 500 | X30: =IF(W30>=0,W30,0) -> 500 | Y30: =IF(W30<=0,W30,0) -> 0 | Z30: 0 | AA30: =+Y30+Z30 -> 0 | AB30: =+O30-X30+Z30+AA30 -> -500 | AD30: DEV FIANZA 7/10
A31: 1 | B31: RUBEN BERMEJO | C31: AVEO|2022|VINO|P62BHW | D31: OHLM037480340 | E31: ASHC | F31: BYER | G31: UBER | H31: 0 | I31: 0 | J31: 0 | K31: 0 | L31: 0 | M31: 0 | N31: 0 | O31: =IF(H31+I31<0,SUM(J31:N31),SUM(H31:N31)) -> 0 | P31: 0 | Q31: 0 | R31: 500 | S31: 0 | T31: 0 | U31: 0 | V31: 0 | W31: =SUM(O31:V31) -> 500 | X31: =IF(W31>=0,W31,0) -> 500 | Y31: =IF(W31<=0,W31,0) -> 0 | Z31: 0 | AA31: =+Y31+Z31 -> 0 | AB31: =+O31-X31+Z31+AA31 -> -500 | AD31: ULTIMO PAGO DE FIANZA
A32: 1 | B32: FIDEL ALEJANDRO SANCHEZ VERGARA | C32: VERSA|2023|PLATA|NCT814A | D32: OHLM031491780 | E32: ASHC | F32: ASHC | G32: UBER | H32: 0 | I32: 0 | J32: 0 | K32: 0 | L32: 0 | M32: 0 | N32: 0 | O32: =IF(H32+I32<0,SUM(J32:N32),SUM(H32:N32)) -> 0 | P32: 0 | Q32: 0 | R32: 500 | S32: 0 | T32: 0 | U32: 0 | V32: 0 | W32: =SUM(O32:V32) -> 500 | X32: =IF(W32>=0,W32,0) -> 500 | Y32: =IF(W32<=0,W32,0) -> 0 | Z32: 0 | AA32: =+Y32+Z32 -> 0 | AB32: =+O32-X32+Z32+AA32 -> -500 | AD32: DEV DE FIANZA 3/7
A33: 1 | B33: JOSE LUIS HERNANDEZ MEDINA | C33: AVEO|2018|GRIS|X59AWG | D33: OHLM031409063 | E33: ASHC | F33: ASHC | G33: UBER | H33: 0 | I33: 0 | J33: 0 | K33: 0 | L33: 0 | M33: 0 | N33: 0 | O33: =IF(H33+I33<0,SUM(J33:N33),SUM(H33:N33)) -> 0 | P33: 0 | Q33: 0 | R33: 0 | S33: 0 | T33: -700 | U33: 0 | V33: 0 | W33: =SUM(O33:V33) -> -700 | X33: =IF(W33>=0,W33,0) -> 0 | Y33: =IF(W33<=0,W33,0) -> -700 | Z33: 700 | AA33: =+Y33+Z33 -> 0 | AB33: =+O33-X33+Z33+AA33 -> 700 | AD33: TRABAJA APP JG UBER, HOJALATERIA 12/15 - PAGA 700 7 ENE
A34: 1 | B34: ALFONSO GONZALEZ MORALES | C34: SWIFT|2017|ROJO|X89ALV | D34: OHLM032370090 | E34: BYER | F34: BYER | G34: UBER | H34: 5950.53 | I34: -2088.56 | J34: -14.4 | K34: 14.69 | L34: 0 | M34: -62 | N34: 0 | O34: =IF(H34+I34<0,SUM(J34:N34),SUM(H34:N34)) -> 3800.26 | P34: -2500 | Q34: -600 | R34: 0 | S34: 0 | T34: -700 | U34: 0 | V34: 0 | W34: =SUM(O34:V34) -> 0.26 | X34: =IF(W34>=0,W34,0) -> 0.26 | Y34: =IF(W34<=0,W34,0) -> 0 | Z34: 0 | AA34: =+Y34+Z34 -> 0 | AB34: =+O34-X34+Z34+AA34 -> 3800 | AD34: ADEUDO SEMANA PASADA A 12%,HOJALATERIA 7/8
A35: 1 | B35: CRISTIAN HERNANDEZ MUNGUIA | C35: AVEOH|2026|ACERO|NEJ990C | D35: SIN TAG | E35: ASHC | F35: ASHC | G35: UBER | H35: 5116.35 | I35: -556.69 | J35: -11.68 | K35: 0 | L35: 0 | M35: -60 | N35: 0 | O35: =IF(H35+I35<0,SUM(J35:N35),SUM(H35:N35)) -> 4487.98 | P35: -1764.42 | Q35: 0 | R35: -500 | S35: 0 | T35: 0 | U35: 0 | V35: 0 | W35: =SUM(O35:V35) -> 2223.56 | X35: =IF(W35>=0,W35,0) -> 2223.56 | Y35: =IF(W35<=0,W35,0) -> 0 | Z35: 0 | AA35: =+Y35+Z35 -> 0 | AB35: =+O35-X35+Z35+AA35 -> 2264.42 | AD35: CTA PROP TRABAJO EN PLAT 1 DÍA 2,500 SEM RESTANTE 2,700.. FIANZA 6/11
A36: 1 | B36: EDUARDO LICONA GODINEZ | C36: KIA RIO|2020|ROJO|MFP751C | D36: OHLM036759090 | E36: ASHC | F36: ASHC | G36: UBER | H36: 5671.6 | I36: -4668.93 | J36: -18.88 | K36: 11.27 | L36: -64.21 | M36: -65 | N36: 0 | O36: =IF(H36+I36<0,SUM(J36:N36),SUM(H36:N36)) -> 865.85 | P36: -2500 | Q36: 6 | R36: -500 | S36: 0 | T36: 0 | U36: 0 | V36: 0 | W36: =SUM(O36:V36) -> -2128.15 | X36: =IF(W36>=0,W36,0) -> 0 | Y36: =IF(W36<=0,W36,0) -> -2128.15 | Z36: 2128 | AA36: =+Y36+Z36 -> -0.15 | AB36: =+O36-X36+Z36+AA36 -> 2993.7 | AD36: FIANZA 4/9 - PAGA 2,182 7 ENE
A37: 1 | B37: FERNANDO GARRIDO GARNICA | C37: AVEO|2018|ROJO|R51BKD | D37: OHLM032762106 | E37: U64 | F37: BYER | G37: UBER | H37: 5154.64 | I37: -2256.03 | J37: -17.28 | K37: 0 | L37: 0 | M37: -65 | N37: 0 | O37: =IF(H37+I37<0,SUM(J37:N37),SUM(H37:N37)) -> 2816.33 | P37: -2500 | Q37: 0 | R37: -500 | S37: 0 | T37: 0 | U37: 0 | V37: 0 | W37: =SUM(O37:V37) -> -183.67 | X37: =IF(W37>=0,W37,0) -> 0 | Y37: =IF(W37<=0,W37,0) -> -183.67 | Z37: 0 | AA37: =+Y37+Z37 -> -183.67 | AB37: =+O37-X37+Z37+AA37 -> 2632.66 | AD37: FIANZA 4/11
... A39: 1 | B39: IVAN MOGUEL PULIDO | C39: KIA RIO|2023|ROJO|H99BLC | D39: OHLM035993526 | E39: U64 | F39: BYER | G39: UBER | H39: 6575.11 | I39: -4131.59 | J39: -14.88 | K39: 0 | L39: -65.54 | M39: -65 | N39: 0 | O39: =IF(H39+I39<0,SUM(J39:N39),SUM(H39:N39)) -> 2298.1 | P39: -1250 | Q39: 0 | R39: 0 | S39: 0 | T39: 0 | U39: 0 | V39: 0 | W39: =SUM(O39:V39) -> 1048.1 | X39: =IF(W39>=0,W39,0) -> 1048.1 | Y39: =IF(W39<=0,W39,0) -> 0 | Z39: 0 | AA39: =+Y39+Z39 -> 0 | AB39: =+O39-X39+Z39+AA39 -> 1250 | AD39: REDUCCION DE CTA 1/2
A40: 1 | B40: RUBI ROBLES SALMERON | C40: BEAT|2020|GRIS|NFN014B | D40: OHLM032762148 | E40: U64 | F40: BYER | G40: UBER | H40: 4207.92 | I40: -1148.34 | J40: -18.88 | K40: 0 | L40: 0 | M40: -65 | N40: 0 | O40: =IF(H40+I40<0,SUM(J40:N40),SUM(H40:N40)) -> 2975.7 | P40: -2500 | Q40: -679 | R40: 0 | S40: 0 | T40: -500 | U40: 0 | V40: 0 | W40: =SUM(O40:V40) -> -703.3 | X40: =IF(W40>=0,W40,0) -> 0 | Y40: =IF(W40<=0,W40,0) -> -703.3 | Z40: =503+200 -> 703 | AA40: =+Y40+Z40 -> -0.3 | AB40: =+O40-X40+Z40+AA40 -> 3678.4 | AD40: HOJALATERIA 7/18,PROMESA DE PAGO DIA MARTES NO CONTESTA. PAGA 503 10 ENE Y 200 11 ENE
A41: 1 | B41: VICTOR HUGO RUIZ CASTILLO | C41: VERSA|2021|BLANCO|MEE228C | D41: OHLM036759082 | E41: ASHC | F41: BYER | G41: UBER | H41: 1302.83 | I41: -269.92 | J41: -4.48 | K41: 0 | L41: -18.81 | M41: -65 | N41: 0 | O41: =IF(H41+I41<0,SUM(J41:N41),SUM(H41:N41)) -> 944.62 | P41: -2500 | Q41: -87 | R41: -500 | S41: 0 | T41: 0 | U41: 0 | V41: 0 | W41: =SUM(O41:V41) -> -2142.38 | X41: =IF(W41>=0,W41,0) -> 0 | Y41: =IF(W41<=0,W41,0) -> -2142.38 | Z41: 2000 | AA41: =+Y41+Z41 -> -142.38 | AB41: =+O41-X41+Z41+AA41 -> 2802.24 | AD41: FIANZA 4/10, PROM PAGO DIA MARTES, PAGA 2,000 7 ENE
...

Sheet Gastos 2025
A1: Semana | B1: MES | C1: Fecha | D1: Solicitante | E1: CONCEPTO | F1: DETALLE | G1: CONDUCTOR | H1: DETALLE | I1: PTTO | J1: SOCIO | K1: METODO DE PAGO | L1: PLAN | M1: REAL | N1: INGRESOS | O1: COMERCIO | P1: COMENTARIOS | Q1: ADICIONAL
A2: =WEEKNUM(C2) -> 36 | B2: 9 | C2: 45901 | D2: NAYE | F2: PRESUPUESTOS | H2: ADMINISTRATIVO | J2: ASHC | N2: =21060+1500+500+330+15100 -> 38490 | P2: VARIOS PRESUPUESTOS | Q2: 21,060 DEPOSITO NAYE BBVA, 1,500 EFECTIVO YUL, 500 EFECTIVO YUL, 330 CUENTA DE FERNANDO F, 15,100 DEPOISITO 11-09
A3: =WEEKNUM(C3) -> 34 | B3: 8 | C3: 45891 | D3: NAYE | F3: PAGO DE GESTORIA JG | H3: VENTO|2019|BLANCO|MGC410C | I3: REAL | J3: JGD | M3: 1300 | P3: PAGA SANTIAGO CON BBVA ORO | Q3: -
A4: =WEEKNUM(C4) -> 34 | B4: 8 | C4: 45891 | D4: NAYE | F4: PAGO DE GESTORIA JG | H4: VENTO|2020|GRIS|MGC414C | I4: REAL | J4: JGD | M4: 1300 | P4: PAGA SANTIAGO CON BBVA ORO | Q4: -
A5: =WEEKNUM(C5) -> 34 | B5: 8 | C5: 45891 | D5: NAYE | F5: PAGO DE GESTORIA JG | H5: MARCH|2021|BLANCO|MGC417C | I5: REAL | J5: JGD | M5: 1300 | P5: PAGA SANTIAGO CON BBVA ORO | Q5: -
A6: =WEEKNUM(C6) -> 34 | B6: 8 | C6: 45892 | D6: NAYE | F6: SOLDADURA DEL PEDAL DEL CLUTCH | H6: MARCH|2020|TURQ|NI5BKD | I6: REAL | J6: ASHC | M6: 400 | P6: PENDIENTE NAYE | Q6: -
A7: =WEEKNUM(C7) -> 35 | B7: 8 | C7: 45899 | D7: NAYE | F7: BASURA | H7: ADMINISTRATIVO | I7: REAL | J7: ASHC | M7: 50 | P7: PENDIENTE NAYE | Q7: -
A8: =WEEKNUM(C8) -> 36 | B8: 9 | C8: 45902 | D8: NAYE | F8: PAGO DE HOJALATERIA | H8: CAMIONETA SUSUKI EXTERNA | I8: REAL | J8: ASHC | M8: 4800 | P8: SE PAGA CON EL SALDO DE SANTIAGO | Q8: -
A9: =WEEKNUM(C9) -> 36 | B9: 9 | C9: 45902 | D9: NAYE | F9: GASOLINA PARA MOTO VENTO OP. | H9: MOTO OPERATIVA | I9: REAL | J9: ASHC | M9: 100 | P9: PENDIENTE A GABRIEL | Q9: -
A10: =WEEKNUM(C10) -> 36 | B10: 9 | C10: 45902 | D10: NAYE | F10: VENTA DE GASOLINA +10% | H10: VERSA|2023|PLATA|NCT814A | I10: REAL | J10: ASHC | M10: 1000 | P10: PENDIENTE NAYE | Q10: -
A11: =WEEKNUM(C11) -> 36 | B11: 9 | C11: 45902 | D11: NAYE | F11: REPARACIÓN DE LLANTA | H11: MARCH|2020|TURQ|MAY737C | I11: REAL | J11: BYER | M11: 350 | P11: DESCUENTO A YOSHUA | Q11: -
A12: =WEEKNUM(C12) -> 36 | B12: 9 | C12: 45902 | D12: NAYE | F12: BALERO DELANTERO IZQUIERDO | H12: VERSA|2020|ROJO|NLP172B | I12: REAL | J12: ASHC | M12: 270 | P12: PENDIENTE A ANGEL | Q12: -
A13: =WEEKNUM(C13) -> 36 | B13: 9 | C13: 45902 | D13: NAYE | F13: FOCO PARA DIRECCIONAL | H13: MARCH|2020|TURQ|NI5BKD | I13: REAL | J13: ASHC | M13: 40 | P13: PENDIENTE A ANGEL | Q13: -
A14: =WEEKNUM(C14) -> 36 | B14: 9 | C14: 45902 | D14: NAYE | F14: TALACHA DE LLANTA TRASERA | H14: AVEO|2018|GRIS|X59AWG | I14: REAL | J14: ASHC | M14: 100 | P14: PENDIENTE NAYE | Q14: -
... A35: =WEEKNUM(C35) -> 37 | B35: 9 | C35: 45908 | D35: NAYE | F35: MANO DE OBRA CAMBIO DE BALERO | H35: VERSA|2023|PLATA|NCT814A | I35: REAL | J35: ASHC | M35: 120 | P35: 1500 EFECTIVO YUL | Q35: -
A36: =WEEKNUM(C36) -> 37 | B36: 9 | C36: 45908 | D36: NAYE | E36: AFINACION | F36: LIQUIDO DE FRENOS | H36: KIA RIO|2020|AZUL|LUE960C | I36: REAL | J36: JGD | M36: 100 | P36: 1500 EFECTIVO YUL | Q36: -
A37: =WEEKNUM(C37) -> 37 | B37: 9 | C37: 45909 | D37: NAYE | F37: GOMAS DE PISTON CALPIS TRASERO DERECHO | H37: KIA RIO|2020|AZUL|LUE960C | I37: REAL | J37: JGD | M37: 363 | P37: 1500 EFECTIVO YUL | Q37: -
A38: =WEEKNUM(C38) -> 37 | B38: 9 | C38: 45909 | D38: NAYE | F38: TALACHA DE LLANTA TRASERA Y REFACCION | H38: HYUNDAI|2022|PLATA|D40BKD | I38: REAL | J38: ASHC | M38: 150 | P38: 1500 EFECTIVO YUL | Q38: -
A39: =WEEKNUM(C39) -> 37 | B39: 9 | C39: 45910 | D39: NAYE | F39: AMORTIGUADOR IZQUIERDO | H39: VENTO|2018|AMARILLO|PED1652 | I39: REAL | J39: ASHC | L39: 600 | M39: 600 | P39: 500 EFECT YUL | Q39: -
A40: =WEEKNUM(C40) -> 37 | B40: 9 | C40: 45910 | D40: NAYE | F40: 20 LITROS DE GASOLINA | H40: AVEO|2021|GRIS|MLC126A | I40: REAL | J40: ASHC | L40: 250 | M40: 479.8 | P40: PENDIENTE YUL | Q40: BBVA
A41: =WEEKNUM(C41) -> 37 | B41: 9 | C41: 45910 | D41: NAYE | F41: BASURA | H41: ADMINISTRATIVO | I41: REAL | J41: ASHC | L41: 0 | M41: 50 | P41: 15,100 PPTO | Q41: -
A42: =WEEKNUM(C42) -> 37 | B42: 9 | C42: 45911 | D42: NAYE | F42: GALON DE ACEITE | H42: AVEO|2018|GRIS|X59AWG | I42: REAL | J42: ASHC | L42: 555 | M42: 550 | P42: PENDIENTE YUL | Q42: BBVA SE REALIZA CAMBIO EL 12 DE SEP
A43: =WEEKNUM(C43) -> 37 | B43: 9 | C43: 45911 | D43: NAYE | E43: AFINACION | F43: BUJIAS | H43: AVEO|2018|GRIS|X59AWG | I43: REAL | J43: ASHC | L43: 280 | M43: =82*4 -> 328 | P43: PENDIENTE YUL | Q43: BBVA SE CAMBIAN POR MAS REFACCIONES (EN 3 MESES)
A44: =WEEKNUM(C44) -> 37 | B44: 9 | C44: 45911 | D44: NAYE | F44: FILTRO DE AIRE | H44: AVEO|2018|GRIS|X59AWG | I44: REAL | J44: ASHC | L44: 50 | M44: 0 | P44: EN TALLER | Q44: SE REALIZA CAMBIO EL 12 DE SEP
A45: =WEEKNUM(C45) -> 37 | B45: 9 | C45: 45911 | D45: NAYE | F45: FILTRO DE ACEITE | H45: AVEO|2018|GRIS|X59AWG | I45: REAL | J45: ASHC | L45: 35 | M45: 124 | P45: PENDIENTE YUL | Q45: BBVA SE REALIZA CAMBIO EL 12 DE SEP
A46: =WEEKNUM(C46) -> 37 | B46: 9 | C46: 45911 | D46: NAYE | E46: AFINACION | F46: BALATAS DELANTERAS | H46: AVEO|2018|GRIS|X59AWG | I46: REAL | J46: ASHC | L46: 410 | M46: 397 | P46: PENDIENTE YUL | Q46: BBVA SE REALIZA CAMBIO EL 12 DE SEP
A47: =WEEKNUM(C47) -> 37 | B47: 9 | C47: 45911 | D47: NAYE | E47: AFINACION | F47: BALATAS TRASERAS | H47: AVEO|2018|GRIS|X59AWG | I47: REAL | J47: ASHC | L47: 410 | M47: 464 | P47: PENDIENTE YUL | Q47: BBVA EN 3 MESES | T47: -
A48: =WEEKNUM(C48) -> 37 | B48: 9 | C48: 45911 | D48: NAYE | F48: GALON DE ACEITE | H48: MARCH|2021|ROJO|NZU5163 | I48: REAL | J48: ASHC | L48: 555 | M48: 550 | P48: PENDIENTE YUL | Q48: BBVA
A49: =WEEKNUM(C49) -> 37 | B49: 9 | C49: 45911 | D49: NAYE | E49: AFINACION | F49: BUJIAS | H49: MARCH|2021|ROJO|NZU5163 | I49: REAL | J49: ASHC | L49: 200 | M49: 0 | P49: EN TALLER | Q49: -
A50: =WEEKNUM(C50) -> 37 | B50: 9 | C50: 45911 | D50: NAYE | F50: FILTRO DE AIRE | H50: MARCH|2021|ROJO|NZU5163 | I50: REAL | J50: ASHC | L50: 40 | M50: 77 | P50: PENDIENTE YUL | Q50: BBVA
A51: =WEEKNUM(C51) -> 37 | B51: 9 | C51: 45911 | D51: NAYE | F51: FILTRO DE ACEITE | H51: MARCH|2021|ROJO|NZU5163 | I51: REAL | J51: ASHC | L51: 35 | M51: 49 | P51: PENDIENTE YUL | Q51: BBVA
A52: =WEEKNUM(C52) -> 37 | B52: 9 | C52: 45911 | D52: NAYE | E52: AFINACION | F52: BALATAS DELANTERAS | H52: MARCH|2021|ROJO|NZU5163 | I52: REAL | J52: ASHC | L52: 480 | M52: 358 | P52: PENDIENTE YUL | Q52: BBVA
A53: =WEEKNUM(C53) -> 37 | B53: 9 | C53: 45911 | D53: NAYE | F53: GALON DE ACEITE | H53: AVEO|2020|AZUL|D28BET | I53: REAL | J53: ASHC | L53: 555 | M53: 550 | P53: PENDIENTE YUL | Q53: BBVA
A54: =WEEKNUM(C54) -> 37 | B54: 9 | C54: 45911 | D54: NAYE | E54: AFINACION | F54: BUJIAS | H54: AVEO|2020|AZUL|D28BET | I54: REAL | J54: ASHC | L54: 280 | M54: 328 | P54: PENDIENTE YUL | Q54: BBVA
A55: =WEEKNUM(C55) -> 37 | B55: 9 | C55: 45911 | D55: NAYE | F55: FILTRO DE AIRE | H55: AVEO|2020|AZUL|D28BET | I55: REAL | J55: ASHC | L55: 50 | M55: 0 | P55: EN TALLER | Q55: -
A56: =WEEKNUM(C56) -> 37 | B56: 9 | C56: 45911 | D56: NAYE | F56: FILTRO DE ACEITE | H56: AVEO|2020|AZUL|D28BET | I56: REAL | J56: ASHC | L56: 35 | M56: 124 | P56: PENDIENTE YUL | Q56: BBVA
A57: =WEEKNUM(C57) -> 37 | B57: 9 | C57: 45911 | D57: NAYE | E57: AFINACION | F57: BALATAS DELANTERAS | H57: AVEO|2020|AZUL|D28BET | I57: REAL | J57: ASHC | L57: 580 | M57: 397 | P57: PENDIENTE YUL | Q57: BBVA
A58: =WEEKNUM(C58) -> 37 | B58: 9 | C58: 45911 | D58: NAYE | F58: FACTURAS DE GASOLINA | H58: ADMINISTRATIVO | I58: REAL | J58: ASHC | L58: 1500 | M58: 1500 | P58: PENDIENTE YUL | Q58: BBVA
A59: =WEEKNUM(C59) -> 37 | B59: 9 | C59: 45912 | D59: NAYE | F59: ELECTRICO REVISION | H59: VENTO|2017|GRIS|MMA672C | I59: REAL | J59: ASHC | L59: 250 | M59: 250 | P59: 15,100 PPTO
A60: =WEEKNUM(C60) -> 37 | B60: 9 | C60: 45912 | D60: NAYE | F60: VERIFICACIÓN | H60: AVEO|2021|GRIS|MLC126A | I60: REAL | J60: ASHC | L60: 720 | M60: 1131 | P60: 15,100 PPTO
...

Sheet Gastos 2026
A1: SEM | B1: FECHA | C1: MES | D1: INVENTARIO | E1: CONCEPTO | F1: DETALLE | G1: CANTIDAD | H1: UNIDAD | I1: V UNIT | J1: SUBTOTAL | K1: IVA | L1: REAL | M1: PLAN | N1: CONDUCTOR | O1: LLAVE | P1: SOCIO | Q1: RESPONSABLE | R1: METODO DE PAGO | S1: COMERCIO | T1: MARCA | U1: COMENTARIOS | V1: ADICIONAL | W1: FOLIO FISCAL | X1: CÓDIGO TICKET
A2: =WEEKNUM(B2) -> 1 | B2: 46023 | C2: =TEXT(B2,"MMMM") -> enero | D2: NO | E2: GESTORIA | F2: GESTORIA ALTA PLACAS | G2: 1 | H2: SERVICIO | I2: 1200 | J2: 1200 | K2: 0 | L2: 1200 | M2: 0 | N2: N/A | O2: AVEOH|2026|GRIS|NEZ118C | P2: IVETT | Q2: YUL | R2: TRANSFERENCIA | S2: ANTONIO BEDOLLA | W2: N/A | AJ2: PIEZAS
A3: =WEEKNUM(B3) -> 1 | B3: 46023 | C3: =TEXT(B3,"MMMM") -> enero | D3: NO | E3: GESTORIA | F3: GESTORIA ALTA PLACAS | G3: 1 | H3: SERVICIO | I3: 1200 | J3: 1200 | K3: 0 | L3: 1200 | M3: 0 | N3: N/A | O3: AVEOH|2026|GRIS|NEZ115C | P3: IVETT | Q3: YUL | R3: TRANSFERENCIA | S3: ANTONIO BEDOLLA | W3: N/A | AJ3: JUEGO
A4: =WEEKNUM(B4) -> 1 | B4: 46023 | C4: =TEXT(B4,"MMMM") -> enero | D4: NO | E4: GESTORIA | F4: GESTORIA ALTA PLACAS | G4: 1 | H4: SERVICIO | I4: 1200 | J4: 1200 | K4: 0 | L4: 1200 | M4: 0 | N4: N/A | O4: AVEOH|2026|GRIS|NEZ110C | P4: IVETT | Q4: YUL | R4: TRANSFERENCIA | S4: ANTONIO BEDOLLA | W4: N/A | AJ4: LITROS
A5: =WEEKNUM(B5) -> 1 | B5: 46023 | C5: =TEXT(B5,"MMMM") -> enero | D5: NO | E5: GESTORIA | F5: GESTORIA ALTA PLACAS | G5: 1 | H5: SERVICIO | I5: 1200 | J5: 1200 | K5: 0 | L5: 1200 | M5: 0 | N5: N/A | O5: AVEOH|2026|GRIS|NEZ103C | P5: IVETT | Q5: YUL | R5: TRANSFERENCIA | S5: ANTONIO BEDOLLA | W5: N/A | AJ5: SERVICIO
A6: =WEEKNUM(B6) -> 1 | B6: 46023 | C6: =TEXT(B6,"MMMM") -> enero | D6: NO | E6: GESTORIA | F6: GESTORIA ALTA PLACAS | G6: 1 | H6: SERVICIO | I6: 1200 | J6: 1200 | K6: 0 | L6: 1200 | M6: 0 | N6: N/A | O6: AVEO|2022|AZUL|PCH9635 | P6: IVETT | Q6: YUL | R6: TRANSFERENCIA | S6: ANTONIO BEDOLLA | W6: N/A | AJ6: PAQUETE
A7: =WEEKNUM(B7) -> 1 | B7: 46024 | C7: =TEXT(B7,"MMMM") -> enero | D7: NO | E7: GPS | F7: CHIPS GPS | G7: 1 | H7: PIEZAS | I7: 1850 | J7: =+G7*I7 -> 1850 | K7: 0 | L7: =+J7 -> 1850 | M7: 0 | N7: N/A | O7: AVEOH|2026|BLANCO|NJJ925C | P7: ASHC | Q7: SANTIAGO | R7: TRANSFERENCIA | S7: JUAN LOZADA | T7: - | U7: TRANSFIERE ASHC | V7: NO SE ME ENTREGO GASTO
A8: =WEEKNUM(B8) -> 1 | B8: 46024 | C8: =TEXT(B8,"MMMM") -> enero | D8: NO | E8: GPS | F8: CHIPS GPS | G8: 1 | H8: PIEZAS | I8: 1850 | J8: =+G8*I8 -> 1850 | K8: 0 | L8: =+J8 -> 1850 | M8: 0 | N8: N/A | O8: AVEOH|2026|BLANCO|NJG485C | P8: ASHC | Q8: SANTIAGO | R8: TRANSFERENCIA | S8: JUAN LOZADA | T8: - | U8: TRANSFIERE ASHC | V8: NO SE ME ENTREGO GASTO
A9: =WEEKNUM(B9) -> 1 | B9: 46024 | C9: =TEXT(B9,"MMMM") -> enero | D9: NO | E9: GPS | F9: CHIPS GPS | G9: 1 | H9: PIEZAS | I9: 1850 | J9: =+G9*I9 -> 1850 | K9: 0 | L9: =+J9 -> 1850 | M9: 0 | N9: N/A | O9: AVEOH|2026|BLANCO|NJG467C | P9: ASHC | Q9: SANTIAGO | R9: TRANSFERENCIA | S9: JUAN LOZADA | T9: - | U9: TRANSFIERE ASHC | V9: NO SE ME ENTREGO GASTO
A10: =WEEKNUM(B10) -> 1 | B10: 46024 | C10: =TEXT(B10,"MMMM") -> enero | D10: NO | E10: GPS | F10: CHIPS GPS | G10: 1 | H10: PIEZAS | I10: 1850 | J10: =+G10*I10 -> 1850 | K10: 0 | L10: =+J10 -> 1850 | M10: 0 | N10: N/A | O10: AVEOH|2026|BLANCO|NJG464C | P10: ASHC | Q10: SANTIAGO | R10: TRANSFERENCIA | S10: JUAN LOZADA | T10: - | U10: TRANSFIERE ASHC | V10: NO SE ME ENTREGO GASTO
A11: =WEEKNUM(B11) -> 1 | B11: 46024 | C11: =TEXT(B11,"MMMM") -> enero | D11: NO | E11: GPS | F11: CHIPS GPS | G11: 1 | H11: PIEZAS | I11: 1850 | J11: =+G11*I11 -> 1850 | K11: 0 | L11: =+J11 -> 1850 | M11: 0 | N11: N/A | O11: AVEOH|2026|BLANCO|NJG451C | P11: ASHC | Q11: SANTIAGO | R11: TRANSFERENCIA | S11: JUAN LOZADA | T11: - | U11: TRANSFIERE ASHC | V11: NO SE ME ENTREGO GASTO
A12: =WEEKNUM(B12) -> 1 | B12: 46024 | C12: =TEXT(B12,"MMMM") -> enero | D12: NO | E12: GPS | F12: CHIPS GPS | G12: 1 | H12: PIEZAS | I12: 1850 | J12: =+G12*I12 -> 1850 | K12: 0 | L12: =+J12 -> 1850 | M12: 0 | N12: N/A | O12: AVEOH|2026|BLANCO|NJG470C | P12: ASHC | Q12: SANTIAGO | R12: TRANSFERENCIA | S12: JUAN LOZADA | T12: - | U12: TRANSFIERE ASHC | V12: NO SE ME ENTREGO GASTO
A13: =WEEKNUM(B13) -> 1 | B13: 46024 | C13: =TEXT(B13,"MMMM") -> enero | D13: NO | E13: GPS | F13: CHIPS GPS | G13: 1 | H13: PIEZAS | I13: 1850 | J13: =+G13*I13 -> 1850 | K13: 0 | L13: =+J13 -> 1850 | M13: 0 | N13: N/A | O13: AVEOH|2026|GRIS|NEZ118C | P13: IVETT | Q13: SANTIAGO | R13: TRANSFERENCIA | S13: JUAN LOZADA | T13: - | U13: TRANSFIERE ASHC | V13: NO SE ME ENTREGO GASTO
A14: =WEEKNUM(B14) -> 1 | B14: 46024 | C14: =TEXT(B14,"MMMM") -> enero | D14: NO | E14: GPS | F14: CHIPS GPS | G14: 1 | H14: PIEZAS | I14: 1850 | J14: =+G14*I14 -> 1850 | K14: 0 | L14: =+J14 -> 1850 | M14: 0 | N14: N/A | O14: AVEOH|2026|GRIS|NEZ115C | P14: IVETT | Q14: SANTIAGO | R14: TRANSFERENCIA | S14: JUAN LOZADA | T14: - | U14: TRANSFIERE ASHC | V14: NO SE ME ENTREGO GASTO
A15: =WEEKNUM(B15) -> 1 | B15: 46024 | C15: =TEXT(B15,"MMMM") -> enero | D15: NO | E15: GPS | F15: CHIPS GPS | G15: 1 | H15: PIEZAS | I15: 1850 | J15: =+G15*I15 -> 1850 | K15: 0 | L15: =+J15 -> 1850 | M15: 0 | N15: N/A | O15: AVEOH|2026|GRIS|NEZ110C | P15: IVETT | Q15: SANTIAGO | R15: TRANSFERENCIA | S15: JUAN LOZADA | T15: - | U15: TRANSFIERE ASHC | V15: NO SE ME ENTREGO GASTO
A16: =WEEKNUM(B16) -> 1 | B16: 46024 | C16: =TEXT(B16,"MMMM") -> enero | D16: NO | E16: GPS | F16: CHIPS GPS | G16: 1 | H16: PIEZAS | I16: 1850 | J16: =+G16*I16 -> 1850 | K16: 0 | L16: =+J16 -> 1850 | M16: 0 | N16: N/A | O16: AVEOH|2026|GRIS|NEZ103C | P16: IVETT | Q16: SANTIAGO | R16: TRANSFERENCIA | S16: JUAN LOZADA | T16: - | U16: TRANSFIERE ASHC | V16: NO SE ME ENTREGO GASTO
A17: =WEEKNUM(B17) -> 1 | B17: 46024 | C17: =TEXT(B17,"MMMM") -> enero | D17: NO | E17: TRASLADO | F17: GASOLINA | G17: 1 | H17: SERVICIO | I17: 250 | J17: 215.51724 | K17: 34.482759 | L17: 250 | M17: 0 | N17: S/C | O17: AVEOH|2026|ROJO|NEZ101C | P17: ASHC | Q17: ISMAEL | R17: TC PLATA ASHC | S17: PEMEX | T17: - | U17: - | V17: NO SE ME ENTREGO GASTO
A18: =WEEKNUM(B18) -> 1 | B18: 46024 | C18: =TEXT(B18,"MMMM") -> enero | D18: NO | E18: TRASLADO | F18: GASOLINA | G18: 1 | H18: SERVICIO | I18: 250 | J18: 215.51724 | K18: 34.482759 | L18: 250 | M18: 0 | N18: S/C | O18: AVEOH|2026|ROJO|NEZ108C | P18: ASHC | Q18: ISMAEL | R18: TC DIDI ASHC | S18: PEMEX | T18: - | U18: - | V18: NO SE ME ENTREGO GASTO
A19: =WEEKNUM(B19) -> 1 | B19: 46024 | C19: =TEXT(B19,"MMMM") -> enero | D19: NO | E19: DERECHOS | F19: VERIFICACIÓN | G19: 1 | H19: SERVICIO | I19: 1154 | J19: 994.82759 | K19: 159.17241 | L19: 1154 | M19: 0 | N19: S/C | O19: AVEOH|2026|ROJO|NEZ101C | P19: ASHC | Q19: ALEJANDRA | R19: TC PLATA ASHC | S19: GOBIERNO EDOMEX | T19: - | U19: - | V19: NO SE ME ENTREGO GASTO
A20: =WEEKNUM(B20) -> 1 | B20: 46024 | C20: =TEXT(B20,"MMMM") -> enero | D20: NO | E20: DERECHOS | F20: VERIFICACIÓN | G20: 1 | H20: SERVICIO | I20: 1154 | J20: 994.82759 | K20: 159.17241 | L20: 1154 | M20: 0 | N20: S/C | O20: AVEOH|2026|ROJO|NEZ108C | P20: ASHC | Q20: ALEJANDRA | R20: TC DIDI ASHC | S20: GOBIERNO EDOMEX | T20: - | U20: - | V20: NO SE ME ENTREGO GASTO
A21: =WEEKNUM(B21) -> 1 | B21: 46025 | C21: =TEXT(B21,"MMMM") -> enero | D21: NO | E21: MTTO | F21: AMORTIGUADOR DELANTERO DERECHO | G21: 1 | H21: PIEZAS | I21: 853.96 | J21: 853.96 | K21: 0 | L21: 853.96 | M21: 0 | N21: JESUS AURELIO NUNGARAY CASTILLO | O21: MARCH|2021|ROJO|NZU5163 | P21: ASHC | Q21: ISMAEL | R21: TC PLATA ASHC | S21: REFACCIONES VERTIZ | T21: VAZLO | U21: - | V21: NO SE ME ENTREGO GASTO
A22: =WEEKNUM(B22) -> 1 | B22: 46025 | C22: =TEXT(B22,"MMMM") -> enero | D22: NO | E22: MTTO | F22: HUESO | G22: 1 | H22: PIEZAS | I22: 437.72 | J22: 437.72 | K22: 0 | L22: 437.72 | M22: 0 | N22: S/C | O22: VERSA|2022|GRIS|NES596C | P22: ASHC | Q22: ISMAEL | R22: TC PLATA ASHC | S22: REFACCIONES VERTIZ | T22: EAGLEBHP | U22: - | V22: NO SE ME ENTREGO GASTO
A23: =WEEKNUM(B23) -> 1 | B23: 46025 | C23: =TEXT(B23,"MMMM") -> enero | D23: NO | E23: MTTO | F23: DEPOSITO DE ANTICONGELANTE | G23: 1 | H23: PIEZAS | I23: 550 | J23: 550 | K23: 0 | L23: 550 | M23: 0 | N23: ALEJANDRO PAZ CAMACHO | O23: MARCH|2020|TURQ|N15BKD | P23: ASHC | Q23: ISMAEL | R23: TC PLATA ASHC | S23: AUTOPARTES LOCAR | T23: ORIGINAL | U23: SE FACTURA A NOMBRE DE YULIANA | V23: NO SE ME ENTREGO GASTO
A24: =WEEKNUM(B24) -> 1 | B24: 46025 | C24: =TEXT(B24,"MMMM") -> enero | D24: NO | E24: MTTO | F24: MARCHA | G24: 1 | H24: PIEZAS | I24: 2100 | J24: 2100 | K24: 0 | L24: 2100 | M24: 0 | N24: EDUARDO LICONA GODINEZ | O24: KIA RIO|2020|ROJO|MFP751C | P24: ASHC | Q24: ISMAEL | R24: EFECTIVO | S24: AUTOPARTES ELECTRICAS ROMERO | T24: VALUE | U24: PEND A SR ISMAEL | V24: NO SE ME ENTREGO GASTO
A25: =WEEKNUM(B25) -> 1 | B25: 46025 | C25: =TEXT(B25,"MMMM") -> enero | D25: NO | E25: MTTO | F25: MANO DE OBRA MARCHA | G25: 1 | H25: SERVICIO | I25: 250 | J25: 250 | K25: 0 | L25: 250 | M25: 0 | N25: EDUARDO LICONA GODINEZ | O25: KIA RIO|2020|ROJO|MFP751C | P25: ASHC | Q25: ISMAEL | R25: EFECTIVO | S25: - | T25: - | U25: PEND A SR ISMAEL | V25: NO SE ME ENTREGO GASTO
A26: =WEEKNUM(B26) -> 1 | B26: 46025 | C26: =TEXT(B26,"MMMM") -> enero | D26: NO | E26: MTTO | F26: FOCOS PELLIZCO (4) | G26: 4 | H26: PIEZAS | I26: 7.5 | J26: 30 | K26: 0 | L26: 30 | M26: 0 | N26: N/A | O26: TALLER | P26: ASHC | Q26: ISMAEL | R26: EFECTIVO | S26: - | T26: - | U26: PEND A SR ISMAEL | V26: NO SE ME ENTREGO GASTO
A27: =WEEKNUM(B27) -> 1 | B27: 46025 | C27: =TEXT(B27,"MMMM") -> enero | D27: NO | E27: TRASLADO | F27: TAXI | G27: 1 | H27: PAQUETE | I27: 100 | J27: 100 | K27: 0 | L27: 100 | M27: 0 | N27: N/A | O27: OPERACIÓN | P27: ASHC | R27: EFECTIVO | S27: CDMX | T27: CALLE | U27: PEND A SR ISMAEL | V27: NO EMITE FACTURA/NO SE ME ENTREGO GASTO | W27: N/A
A28: =WEEKNUM(B28) -> 1 | B28: 46025 | C28: =TEXT(B28,"MMMM") -> enero | D28: NO | E28: GASOLINA | F28: FACTURAS | G28: 1 | H28: PAQUETE | I28: 1500 | J28: 1500 | K28: 0 | L28: 1500 | M28: 0 | N28: N/A | O28: ADMINISTRACIÓN | P28: ASHC | Q28: YUL | R28: TRANSFERENCIA | S28: ENRIQUE | T28: N/A | U28: $3400 DE CUENTA YOSHUA ASHC | W28: N/A
A29: =WEEKNUM(B29) -> 2 | B29: 46027 | C29: =TEXT(B29,"MMMM") -> enero | D29: NO | E29: MTTO | F29: SOPORTE FRONTAL DERECHO | G29: 1 | H29: PIEZAS | I29: 764.6488 | J29: 764.6488 | K29: 0 | L29: 764.6488 | M29: 0 | N29: KEVIN ALEXIS MERLOS CORTES | O29: VENTO|2020|GRIS|R66BER | P29: ASHC | Q29: ISMAEL | R29: TC DIDI ASHC | S29: REFACCIONES VERTIZ | T29: VAZLO | U29: DIDI ASHC | V29: NO SE ME ENTREGO GASTO
